Workbook

Sheet MAIN
A4: Rotterdam Singapore | C4: VLCC | F4: SUEZMAX | J4: AFRAMAX
B5: VS Barges | C5: =IF(DAY(C$6)<15,"1H-"&VLOOKUP(MONTH(C$6),Mapping!$A$1:$B$12,2,0),"2H-"&VLOOKUP(MONTH(C$6),Mapping!$A$1:$B$12,2,0)) -> 2H-OCT | D5: =IF(DAY(D$6)<15,"1H-"&VLOOKUP(MONTH(D$6),Mapping!$A$1:$B$12,2,0),"2H-"&VLOOKUP(MONTH(D$6),Mapping!$A$1:$B$12,2,0)) -> 1H-NOV | F5: =IF(DAY(F$6)<15,"1H-"&VLOOKUP(MONTH(F$6),Mapping!$A$1:$B$12,2,0),"2H-"&VLOOKUP(MONTH(F$6),Mapping!$A$1:$B$12,2,0)) -> 2H-SEP | G5: =IF(DAY(G$6)<15,"1H-"&VLOOKUP(MONTH(G$6),Mapping!$A$1:$B$12,2,0),"2H-"&VLOOKUP(MONTH(G$6),Mapping!$A$1:$B$12,2,0)) -> 1H-OCT | H5: =IF(DAY(H$6)<15,"1H-"&VLOOKUP(MONTH(H$6),Mapping!$A$1:$B$12,2,0),"2H-"&VLOOKUP(MONTH(H$6),Mapping!$A$1:$B$12,2,0)) -> 2H-OCT | J5: =IF(DAY(J$6)<15,"1H-"&VLOOKUP(MONTH(J$6),Mapping!$A$1:$B$12,2,0),"2H-"&VLOOKUP(MONTH(J$6),Mapping!$A$1:$B$12,2,0)) -> 2H-SEP | K5: =IF(DAY(K$6)<15,"1H-"&VLOOKUP(MONTH(K$6),Mapping!$A$1:$B$12,2,0),"2H-"&VLOOKUP(MONTH(K$6),Mapping!$A$1:$B$12,2,0)) -> 1H-OCT | L5: =IF(DAY(L$6)<15,"1H-"&VLOOKUP(MONTH(L$6),Mapping!$A$1:$B$12,2,0),"2H-"&VLOOKUP(MONTH(L$6),Mapping!$A$1:$B$12,2,0)) -> 2H-OCT
B6: VS Barges | C6: ='ROTT TO SING'!E26 -> 45955 | D6: ='ROTT TO SING'!G26 -> 45969 | F6: ='ROTT TO SING'!N26 -> 45930 | G6: ='ROTT TO SING'!P26 -> 45944 | H6: ='ROTT TO SING'!R26 -> 45958 | J6: ='ROTT TO SING'!Y26 -> 45930 | K6: ='ROTT TO SING'!AA26 -> 45944 | L6: ='ROTT TO SING'!AC26 -> 45958
A7: RMG | C7: =C27+C8-C9 -> -22.456935 | D7: =D27+D8-D9 -> -22.181283 | F7: =F27+F8-F9 -> -36.773688 | G7: =G27+G8-G9 -> -36.647188 | H7: =H27+H8-H9 -> -36.485471 | J7: =J27+J8-J9 -> -49.545932 | K7: =K27+K8-K9 -> -49.419432 | L7: =L27+L8-L9 -> -49.257716
B8: Sale Premium | C8: =INDEX(Premium!$A$2:$D$12,MATCH(MAIN!$A7,Premium!$A$2:$A$12,0),MATCH(EOMONTH(MAIN!C6,-1)+1,Premium!$A$2:$D$2,0)) -> -1.5 | D8: =INDEX(Premium!$A$2:$D$12,MATCH(MAIN!$A7,Premium!$A$2:$A$12,0),MATCH(EOMONTH(MAIN!D6,-1)+1,Premium!$A$2:$D$2,0)) -> -1.5 | E8: Sale premium | F8: =INDEX(Premium!$A$2:$D$12,MATCH(MAIN!$A7,Premium!$A$2:$A$12,0),MATCH(EOMONTH(MAIN!F6,-1)+1,Premium!$A$2:$D$2,0)) -> -1.5 | G8: =INDEX(Premium!$A$2:$D$12,MATCH(MAIN!$A7,Premium!$A$2:$A$12,0),MATCH(EOMONTH(MAIN!G6,-1)+1,Premium!$A$2:$D$2,0)) -> -1.5 | H8: =INDEX(Premium!$A$2:$D$12,MATCH(MAIN!$A7,Premium!$A$2:$A$12,0),MATCH(EOMONTH(MAIN!H6,-1)+1,Premium!$A$2:$D$2,0)) -> -1.5 | I8: Sale premium | J8: =INDEX(Premium!$A$2:$D$12,MATCH(MAIN!$A7,Premium!$A$2:$A$12,0),MATCH(EOMONTH(MAIN!J6,-1)+1,Premium!$A$2:$D$2,0)) -> -1.5 | K8: =INDEX(Premium!$A$2:$D$12,MATCH(MAIN!$A7,Premium!$A$2:$A$12,0),MATCH(EOMONTH(MAIN!K6,-1)+1,Premium!$A$2:$D$2,0)) -> -1.5 | L8: =INDEX(Premium!$A$2:$D$12,MATCH(MAIN!$A7,Premium!$A$2:$A$12,0),MATCH(EOMONTH(MAIN!L6,-1)+1,Premium!$A$2:$D$2,0)) -> -1.5
B9: Purchase Premium | C9: =INDEX(Premium!$A$21:$D$29,MATCH(MAIN!$A7,Premium!$A$21:$A$29,0),MATCH(EOMONTH(MAIN!C28,-1)+1,Premium!$A$21:$D$21,0)) -> 3 | D9: =INDEX(Premium!$A$21:$D$29,MATCH(MAIN!$A7,Premium!$A$21:$A$29,0),MATCH(EOMONTH(MAIN!D28,-1)+1,Premium!$A$21:$D$21,0)) -> 3 | E9: Purchase Prem VS Barges | F9: =INDEX(Premium!$A$21:$D$29,MATCH(MAIN!$A7,Premium!$A$21:$A$29,0),MATCH(EOMONTH(MAIN!F28,-1)+1,Premium!$A$21:$D$21,0)) -> 3 | G9: =INDEX(Premium!$A$21:$D$29,MATCH(MAIN!$A7,Premium!$A$21:$A$29,0),MATCH(EOMONTH(MAIN!G28,-1)+1,Premium!$A$21:$D$21,0)) -> 3 | H9: =INDEX(Premium!$A$21:$D$29,MATCH(MAIN!$A7,Premium!$A$21:$A$29,0),MATCH(EOMONTH(MAIN!H28,-1)+1,Premium!$A$21:$D$21,0)) -> 3 | I9: Purchase Prem VS Barges | J9: =INDEX(Premium!$A$21:$D$29,MATCH(MAIN!$A7,Premium!$A$21:$A$29,0),MATCH(EOMONTH(MAIN!J28,-1)+1,Premium!$A$21:$D$21,0)) -> 3 | K9: =INDEX(Premium!$A$21:$D$29,MATCH(MAIN!$A7,Premium!$A$21:$A$29,0),MATCH(EOMONTH(MAIN!K28,-1)+1,Premium!$A$21:$D$21,0)) -> 3 | L9: =INDEX(Premium!$A$21:$D$29,MATCH(MAIN!$A7,Premium!$A$21:$A$29,0),MATCH(EOMONTH(MAIN!L28,-1)+1,Premium!$A$21:$D$21,0)) -> 3
B10: Freight | C10: =INDEX('ROTT TO SING'!$A$8:$H$25,MATCH(MAIN!B10,'ROTT TO SING'!$A$8:$A$25,0),5) -> 20.740741 | D10: =INDEX('ROTT TO SING'!$A$8:$H$25,MATCH(MAIN!B10,'ROTT TO SING'!$A$8:$A$25,0),7) -> 20.740741 | E10: Freight | F10: =INDEX('ROTT TO SING'!$J$8:$S$25,MATCH(MAIN!E10,'ROTT TO SING'!$J$8:$J$25,0),5) -> 34 | G10: =INDEX('ROTT TO SING'!$J$8:$S$25,MATCH(MAIN!E10,'ROTT TO SING'!$J$8:$J$25,0),7) -> 34 | H10: =INDEX('ROTT TO SING'!$J$8:$S$25,MATCH(MAIN!E10,'ROTT TO SING'!$J$8:$J$25,0),9) -> 34 | I10: Freight | J10: =INDEX('ROTT TO SING'!$U$8:$AD$25,MATCH(MAIN!I10,'ROTT TO AG'!$L$6:$L$23,0),5) -> 46.938776 | K10: =INDEX('ROTT TO SING'!$U$8:$AD$25,MATCH(MAIN!I10,'ROTT TO AG'!$L$6:$L$23,0),7) -> 46.938776 | L10: =INDEX('ROTT TO SING'!$U$8:$AD$25,MATCH(MAIN!I10,'ROTT TO AG'!$L$6:$L$23,0),9) -> 46.938776
B11: Volume | C11: =INDEX('ROTT TO SING'!$A$8:$H$25,MATCH(MAIN!B11,'ROTT TO SING'!$A$8:$A$25,0),5) -> 0 | D11: =INDEX('ROTT TO SING'!$A$8:$H$25,MATCH(MAIN!B11,'ROTT TO SING'!$A$8:$A$25,0),7) -> 0 | E11: Volume | F11: =INDEX('ROTT TO SING'!$J$8:$S$25,MATCH(MAIN!E11,'ROTT TO SING'!$J$8:$J$25,0),5) -> 0 | G11: =INDEX('ROTT TO SING'!$J$8:$S$25,MATCH(MAIN!E11,'ROTT TO SING'!$J$8:$J$25,0),7) -> 0 | H11: =INDEX('ROTT TO SING'!$J$8:$S$25,MATCH(MAIN!E11,'ROTT TO SING'!$J$8:$J$25,0),9) -> 0 | I11: Volume | J11: =INDEX('ROTT TO SING'!$U$8:$AD$25,MATCH(MAIN!I11,'ROTT TO AG'!$L$6:$L$23,0),5) -> 0 | K11: =INDEX('ROTT TO SING'!$U$8:$AD$25,MATCH(MAIN!I11,'ROTT TO AG'!$L$6:$L$23,0),7) -> 0 | L11: =INDEX('ROTT TO SING'!$U$8:$AD$25,MATCH(MAIN!I11,'ROTT TO AG'!$L$6:$L$23,0),9) -> 0
B12: Demurrage | C12: =INDEX('ROTT TO SING'!$A$8:$H$25,MATCH(MAIN!B12,'ROTT TO SING'!$A$8:$A$25,0),5) -> 2.037037 | D12: =INDEX('ROTT TO SING'!$A$8:$H$25,MATCH(MAIN!B12,'ROTT TO SING'!$A$8:$A$25,0),7) -> 2.037037 | E12: Demurrage | F12: =INDEX('ROTT TO SING'!$J$8:$S$25,MATCH(MAIN!E12,'ROTT TO SING'!$J$8:$J$25,0),5) -> 2.6833333 | G12: =INDEX('ROTT TO SING'!$J$8:$S$25,MATCH(MAIN!E12,'ROTT TO SING'!$J$8:$J$25,0),7) -> 2.6833333 | H12: =INDEX('ROTT TO SING'!$J$8:$S$25,MATCH(MAIN!E12,'ROTT TO SING'!$J$8:$J$25,0),9) -> 2.6833333 | I12: Demurrage | J12: =INDEX('ROTT TO SING'!$U$8:$AD$25,MATCH(MAIN!I12,'ROTT TO AG'!$L$6:$L$23,0),5) -> 2.1683673 | K12: =INDEX('ROTT TO SING'!$U$8:$AD$25,MATCH(MAIN!I12,'ROTT TO AG'!$L$6:$L$23,0),7) -> 2.1683673 | L12: =INDEX('ROTT TO SING'!$U$8:$AD$25,MATCH(MAIN!I12,'ROTT TO AG'!$L$6:$L$23,0),9) -> 2.1683673
B13: Insurance | C13: =INDEX('ROTT TO SING'!$A$8:$H$25,MATCH(MAIN!B13,'ROTT TO SING'!$A$8:$A$25,0),5) -> 0.031481481 | D13: =INDEX('ROTT TO SING'!$A$8:$H$25,MATCH(MAIN!B13,'ROTT TO SING'!$A$8:$A$25,0),7) -> 0.031481481 | E13: Insurance | F13: =INDEX('ROTT TO SING'!$J$8:$S$25,MATCH(MAIN!E13,'ROTT TO SING'!$J$8:$J$25,0),5) -> 0.056666667 | G13: =INDEX('ROTT TO SING'!$J$8:$S$25,MATCH(MAIN!E13,'ROTT TO SING'!$J$8:$J$25,0),7) -> 0.056666667 | H13: =INDEX('ROTT TO SING'!$J$8:$S$25,MATCH(MAIN!E13,'ROTT TO SING'!$J$8:$J$25,0),9) -> 0.056666667 | I13: Insurance | J13: =INDEX('ROTT TO SING'!$U$8:$AD$25,MATCH(MAIN!I13,'ROTT TO AG'!$L$6:$L$23,0),5) -> 0.086734694 | K13: =INDEX('ROTT TO SING'!$U$8:$AD$25,MATCH(MAIN!I13,'ROTT TO AG'!$L$6:$L$23,0),7) -> 0.086734694 | L13: =INDEX('ROTT TO SING'!$U$8:$AD$25,MATCH(MAIN!I13,'ROTT TO AG'!$L$6:$L$23,0),9) -> 0.086734694
B14: Loading PC | C14: =INDEX('ROTT TO SING'!$A$8:$H$25,MATCH(MAIN!B14,'ROTT TO SING'!$A$8:$A$25,0),5) -> 0.092592593 | D14: =INDEX('ROTT TO SING'!$A$8:$H$25,MATCH(MAIN!B14,'ROTT TO SING'!$A$8:$A$25,0),7) -> 0.092592593 | E14: Loading PC | F14: =INDEX('ROTT TO SING'!$J$8:$S$25,MATCH(MAIN!E14,'ROTT TO SING'!$J$8:$J$25,0),5) -> 0.16666667 | G14: =INDEX('ROTT TO SING'!$J$8:$S$25,MATCH(MAIN!E14,'ROTT TO SING'!$J$8:$J$25,0),7) -> 0.16666667 | H14: =INDEX('ROTT TO SING'!$J$8:$S$25,MATCH(MAIN!E14,'ROTT TO SING'!$J$8:$J$25,0),9) -> 0.16666667 | I14: Loading PC | J14: =INDEX('ROTT TO SING'!$U$8:$AD$25,MATCH(MAIN!I14,'ROTT TO AG'!$L$6:$L$23,0),5) -> 0.25510204 | K14: =INDEX('ROTT TO SING'!$U$8:$AD$25,MATCH(MAIN!I14,'ROTT TO AG'!$L$6:$L$23,0),7) -> 0.25510204 | L14: =INDEX('ROTT TO SING'!$U$8:$AD$25,MATCH(MAIN!I14,'ROTT TO AG'!$L$6:$L$23,0),9) -> 0.25510204
B15: Discharge PC | C15: =INDEX('ROTT TO SING'!$A$8:$H$25,MATCH(MAIN!B15,'ROTT TO SING'!$A$8:$A$25,0),5) -> 0.092592593 | D15: =INDEX('ROTT TO SING'!$A$8:$H$25,MATCH(MAIN!B15,'ROTT TO SING'!$A$8:$A$25,0),7) -> 0.092592593 | E15: Discharge PC | F15: =INDEX('ROTT TO SING'!$J$8:$S$25,MATCH(MAIN!E15,'ROTT TO SING'!$J$8:$J$25,0),5) -> 0.16666667 | G15: =INDEX('ROTT TO SING'!$J$8:$S$25,MATCH(MAIN!E15,'ROTT TO SING'!$J$8:$J$25,0),7) -> 0.16666667 | H15: =INDEX('ROTT TO SING'!$J$8:$S$25,MATCH(MAIN!E15,'ROTT TO SING'!$J$8:$J$25,0),9) -> 0.16666667 | I15: Discharge PC | J15: =INDEX('ROTT TO SING'!$U$8:$AD$25,MATCH(MAIN!I15,'ROTT TO AG'!$L$6:$L$23,0),5) -> 0.25510204 | K15: =INDEX('ROTT TO SING'!$U$8:$AD$25,MATCH(MAIN!I15,'ROTT TO AG'!$L$6:$L$23,0),7) -> 0.25510204 | L15: =INDEX('ROTT TO SING'!$U$8:$AD$25,MATCH(MAIN!I15,'ROTT TO AG'!$L$6:$L$23,0),9) -> 0.25510204
B16: Finance | C16: =INDEX('ROTT TO SING'!$A$8:$H$25,MATCH(MAIN!B16,'ROTT TO SING'!$A$8:$A$25,0),5) -> 3.465 | D16: =INDEX('ROTT TO SING'!$A$8:$H$25,MATCH(MAIN!B16,'ROTT TO SING'!$A$8:$A$25,0),7) -> 3.465 | E16: Finance | F16: =INDEX('ROTT TO SING'!$J$8:$S$25,MATCH(MAIN!E16,'ROTT TO SING'!$J$8:$J$25,0),5) -> 3.465 | G16: =INDEX('ROTT TO SING'!$J$8:$S$25,MATCH(MAIN!E16,'ROTT TO SING'!$J$8:$J$25,0),7) -> 3.465 | H16: =INDEX('ROTT TO SING'!$J$8:$S$25,MATCH(MAIN!E16,'ROTT TO SING'!$J$8:$J$25,0),9) -> 3.4310959 | I16: Finance | J16: =INDEX('ROTT TO SING'!$U$8:$AD$25,MATCH(MAIN!I16,'ROTT TO AG'!$L$6:$L$23,0),5) -> 3.465 | K16: =INDEX('ROTT TO SING'!$U$8:$AD$25,MATCH(MAIN!I16,'ROTT TO AG'!$L$6:$L$23,0),7) -> 3.465 | L16: =INDEX('ROTT TO SING'!$U$8:$AD$25,MATCH(MAIN!I16,'ROTT TO AG'!$L$6:$L$23,0),9) -> 3.4310959
B17: Heat | C17: =INDEX('ROTT TO SING'!$A$8:$H$25,MATCH(MAIN!B17,'ROTT TO SING'!$A$8:$A$25,0),5) -> 0 | D17: =INDEX('ROTT TO SING'!$A$8:$H$25,MATCH(MAIN!B17,'ROTT TO SING'!$A$8:$A$25,0),7) -> 0 | E17: Heat | F17: =INDEX('ROTT TO SING'!$J$8:$S$25,MATCH(MAIN!E17,'ROTT TO SING'!$J$8:$J$25,0),5) -> 0 | G17: =INDEX('ROTT TO SING'!$J$8:$S$25,MATCH(MAIN!E17,'ROTT TO SING'!$J$8:$J$25,0),7) -> 0 | H17: =INDEX('ROTT TO SING'!$J$8:$S$25,MATCH(MAIN!E17,'ROTT TO SING'!$J$8:$J$25,0),9) -> 0 | I17: Heat | J17: =INDEX('ROTT TO SING'!$U$8:$AD$25,MATCH(MAIN!I17,'ROTT TO AG'!$L$6:$L$23,0),5) -> 0 | K17: =INDEX('ROTT TO SING'!$U$8:$AD$25,MATCH(MAIN!I17,'ROTT TO AG'!$L$6:$L$23,0),7) -> 0 | L17: =INDEX('ROTT TO SING'!$U$8:$AD$25,MATCH(MAIN!I17,'ROTT TO AG'!$L$6:$L$23,0),9) -> 0
B18: LC charges | C18: =INDEX('ROTT TO SING'!$A$8:$H$25,MATCH(MAIN!B18,'ROTT TO SING'!$A$8:$A$25,0),5) -> 0.2874375 | D18: =INDEX('ROTT TO SING'!$A$8:$H$25,MATCH(MAIN!B18,'ROTT TO SING'!$A$8:$A$25,0),7) -> 0.2874375 | E18: LC charges | F18: =INDEX('ROTT TO SING'!$J$8:$S$25,MATCH(MAIN!E18,'ROTT TO SING'!$J$8:$J$25,0),5) -> 0.2874375 | G18: =INDEX('ROTT TO SING'!$J$8:$S$25,MATCH(MAIN!E18,'ROTT TO SING'!$J$8:$J$25,0),7) -> 0.2874375 | H18: =INDEX('ROTT TO SING'!$J$8:$S$25,MATCH(MAIN!E18,'ROTT TO SING'!$J$8:$J$25,0),9) -> 0.284625 | I18: LC charges | J18: =INDEX('ROTT TO SING'!$U$8:$AD$25,MATCH(MAIN!I18,'ROTT TO AG'!$L$6:$L$23,0),5) -> 0.2874375 | K18: =INDEX('ROTT TO SING'!$U$8:$AD$25,MATCH(MAIN!I18,'ROTT TO AG'!$L$6:$L$23,0),7) -> 0.2874375 | L18: =INDEX('ROTT TO SING'!$U$8:$AD$25,MATCH(MAIN!I18,'ROTT TO AG'!$L$6:$L$23,0),9) -> 0.284625
B19: Outturn loss | C19: =INDEX('ROTT TO SING'!$A$8:$H$25,MATCH(MAIN!B19,'ROTT TO SING'!$A$8:$A$25,0),5) -> 1.17975 | D19: =INDEX('ROTT TO SING'!$A$8:$H$25,MATCH(MAIN!B19,'ROTT TO SING'!$A$8:$A$25,0),7) -> 1.16925 | E19: Outturn loss | F19: =INDEX('ROTT TO SING'!$J$8:$S$25,MATCH(MAIN!E19,'ROTT TO SING'!$J$8:$J$25,0),5) -> 1.18125 | G19: =INDEX('ROTT TO SING'!$J$8:$S$25,MATCH(MAIN!E19,'ROTT TO SING'!$J$8:$J$25,0),7) -> 1.17975 | H19: =INDEX('ROTT TO SING'!$J$8:$S$25,MATCH(MAIN!E19,'ROTT TO SING'!$J$8:$J$25,0),9) -> 1.17975 | I19: Outturn loss | J19: =INDEX('ROTT TO SING'!$U$8:$AD$25,MATCH(MAIN!I19,'ROTT TO AG'!$L$6:$L$23,0),5) -> 1.18125 | K19: =INDEX('ROTT TO SING'!$U$8:$AD$25,MATCH(MAIN!I19,'ROTT TO AG'!$L$6:$L$23,0),7) -> 1.17975 | L19: =INDEX('ROTT TO SING'!$U$8:$AD$25,MATCH(MAIN!I19,'ROTT TO AG'!$L$6:$L$23,0),9) -> 1.17975
B20: Inspection | C20: =INDEX('ROTT TO SING'!$A$8:$H$25,MATCH(MAIN!B20,'ROTT TO SING'!$A$8:$A$25,0),5) -> 0.046296296 | D20: =INDEX('ROTT TO SING'!$A$8:$H$25,MATCH(MAIN!B20,'ROTT TO SING'!$A$8:$A$25,0),7) -> 0.046296296 | E20: Inspection | F20: =INDEX('ROTT TO SING'!$J$8:$S$25,MATCH(MAIN!E20,'ROTT TO SING'!$J$8:$J$25,0),5) -> 0.083333333 | G20: =INDEX('ROTT TO SING'!$J$8:$S$25,MATCH(MAIN!E20,'ROTT TO SING'!$J$8:$J$25,0),7) -> 0.083333333 | H20: =INDEX('ROTT TO SING'!$J$8:$S$25,MATCH(MAIN!E20,'ROTT TO SING'!$J$8:$J$25,0),9) -> 0.083333333 | I20: Inspection | J20: =INDEX('ROTT TO SING'!$U$8:$AD$25,MATCH(MAIN!I20,'ROTT TO AG'!$L$6:$L$23,0),5) -> 0.12755102 | K20: =INDEX('ROTT TO SING'!$U$8:$AD$25,MATCH(MAIN!I20,'ROTT TO AG'!$L$6:$L$23,0),7) -> 0.12755102 | L20: =INDEX('ROTT TO SING'!$U$8:$AD$25,MATCH(MAIN!I20,'ROTT TO AG'!$L$6:$L$23,0),9) -> 0.12755102
B21: Overage Insurance | C21: =INDEX('ROTT TO SING'!$A$8:$H$25,MATCH(MAIN!B21,'ROTT TO SING'!$A$8:$A$25,0),5) -> 0.0046296296 | D21: =INDEX('ROTT TO SING'!$A$8:$H$25,MATCH(MAIN!B21,'ROTT TO SING'!$A$8:$A$25,0),7) -> 0.0046296296 | E21: Overage Insurance | F21: =INDEX('ROTT TO SING'!$J$8:$S$25,MATCH(MAIN!E21,'ROTT TO SING'!$J$8:$J$25,0),5) -> 0.0083333333 | G21: =INDEX('ROTT TO SING'!$J$8:$S$25,MATCH(MAIN!E21,'ROTT TO SING'!$J$8:$J$25,0),7) -> 0.0083333333 | H21: =INDEX('ROTT TO SING'!$J$8:$S$25,MATCH(MAIN!E21,'ROTT TO SING'!$J$8:$J$25,0),9) -> 0.0083333333 | I21: Overage Insurance | J21: =INDEX('ROTT TO SING'!$U$8:$AD$25,MATCH(MAIN!I21,'ROTT TO AG'!$L$6:$L$23,0),5) -> 0.012755102 | K21: =INDEX('ROTT TO SING'!$U$8:$AD$25,MATCH(MAIN!I21,'ROTT TO AG'!$L$6:$L$23,0),7) -> 0.012755102 | L21: =INDEX('ROTT TO SING'!$U$8:$AD$25,MATCH(MAIN!I21,'ROTT TO AG'!$L$6:$L$23,0),9) -> 0.012755102
... B27: ROLL - COST | C27: =INDEX('ROTT TO SING'!$A$8:$H$25,MATCH(MAIN!B27,'ROTT TO SING'!$A$8:$A$25,0),5) -> -17.956935 | D27: =INDEX('ROTT TO SING'!$A$8:$H$25,MATCH(MAIN!B27,'ROTT TO SING'!$A$8:$A$25,0),7) -> -17.681283 | E27: ROLL - COST | F27: =INDEX('ROTT TO SING'!$J$8:$S$25,MATCH(MAIN!E27,'ROTT TO SING'!$J$8:$J$25,0),5) -> -32.273688 | G27: =INDEX('ROTT TO SING'!$J$8:$S$25,MATCH(MAIN!E27,'ROTT TO SING'!$J$8:$J$25,0),7) -> -32.147188 | H27: =INDEX('ROTT TO SING'!$J$8:$S$25,MATCH(MAIN!E27,'ROTT TO SING'!$J$8:$J$25,0),9) -> -31.985471 | I27: ROLL - COST | J27: =INDEX('ROTT TO SING'!$U$8:$AD$25,MATCH(MAIN!I27,'ROTT TO AG'!$L$6:$L$23,0),5) -> -45.045932 | K27: =INDEX('ROTT TO SING'!$U$8:$AD$25,MATCH(MAIN!I27,'ROTT TO AG'!$L$6:$L$23,0),7) -> -44.919432 | L27: =INDEX('ROTT TO SING'!$U$8:$AD$25,MATCH(MAIN!I27,'ROTT TO AG'!$L$6:$L$23,0),9) -> -44.757716
B28: Loading Month | C28: ='ROTT TO SING'!E5 -> 45910 | D28: ='ROTT TO SING'!G5 -> 45924 | E28: Loading Month | F28: ='ROTT TO SING'!N5 -> 45903 | G28: ='ROTT TO SING'!P5 -> 45917 | H28: ='ROTT TO SING'!R5 -> 45931 | I28: Loading Month | J28: ='ROTT TO SING'!Y5 -> 45903 | K28: ='ROTT TO SING'!AA26 -> 45944 | L28: ='ROTT TO SING'!AC26 -> 45958
A29: RMK | C29: =C49+C30-C31 -> -22.456935 | D29: =D49+D30-D31 -> -22.181283 | F29: =F49+F30-F31 -> -36.773688 | G29: =G49+G30-G31 -> -36.647188 | H29: =H49+H30-H31 -> -36.485471 | J29: =J49+J30-J31 -> -49.545932 | K29: =K49+K30-K31 -> -49.419432 | L29: =L49+L30-L31 -> -49.257716
B30: Sale premium | C30: =INDEX(Premium!$A$2:$D$12,MATCH(MAIN!$A29,Premium!$A$2:$A$12,0),MATCH(EOMONTH(MAIN!C6,-1)+1,Premium!$A$2:$D$2,0)) -> -6.5 | D30: =INDEX(Premium!$A$2:$D$12,MATCH(MAIN!$A29,Premium!$A$2:$A$12,0),MATCH(EOMONTH(MAIN!D6,-1)+1,Premium!$A$2:$D$2,0)) -> -6.5 | E30: Sale premium | F30: =INDEX(Premium!$A$2:$D$12,MATCH(MAIN!$A29,Premium!$A$2:$A$12,0),MATCH(EOMONTH(MAIN!F6,-1)+1,Premium!$A$2:$D$2,0)) -> -6.5 | G30: =INDEX(Premium!$A$2:$D$12,MATCH(MAIN!$A29,Premium!$A$2:$A$12,0),MATCH(EOMONTH(MAIN!G6,-1)+1,Premium!$A$2:$D$2,0)) -> -6.5 | H30: =INDEX(Premium!$A$2:$D$12,MATCH(MAIN!$A29,Premium!$A$2:$A$12,0),MATCH(EOMONTH(MAIN!H6,-1)+1,Premium!$A$2:$D$2,0)) -> -6.5 | I30: Sale premium | J30: =INDEX(Premium!$A$2:$D$12,MATCH(MAIN!$A29,Premium!$A$2:$A$12,0),MATCH(EOMONTH(MAIN!J6,-1)+1,Premium!$A$2:$D$2,0)) -> -6.5 | K30: =INDEX(Premium!$A$2:$D$12,MATCH(MAIN!$A29,Premium!$A$2:$A$12,0),MATCH(EOMONTH(MAIN!K6,-1)+1,Premium!$A$2:$D$2,0)) -> -6.5 | L30: =INDEX(Premium!$A$2:$D$12,MATCH(MAIN!$A29,Premium!$A$2:$A$12,0),MATCH(EOMONTH(MAIN!L6,-1)+1,Premium!$A$2:$D$2,0)) -> -6.5
B31: Purchase Premium | C31: =INDEX(Premium!$A$21:$D$29,MATCH(MAIN!$A29,Premium!$A$21:$A$29,0),MATCH(EOMONTH(MAIN!C50,-1)+1,Premium!$A$21:$D$21,0)) -> -2 | D31: =INDEX(Premium!$A$21:$D$29,MATCH(MAIN!$A29,Premium!$A$21:$A$29,0),MATCH(EOMONTH(MAIN!D50,-1)+1,Premium!$A$21:$D$21,0)) -> -2 | E31: Purchase Prem VS Barges | F31: =INDEX(Premium!$A$21:$D$29,MATCH(MAIN!$A29,Premium!$A$21:$A$29,0),MATCH(EOMONTH(MAIN!F50,-1)+1,Premium!$A$21:$D$21,0)) -> -2 | G31: =INDEX(Premium!$A$21:$D$29,MATCH(MAIN!$A29,Premium!$A$21:$A$29,0),MATCH(EOMONTH(MAIN!G50,-1)+1,Premium!$A$21:$D$21,0)) -> -2 | H31: =INDEX(Premium!$A$21:$D$29,MATCH(MAIN!$A29,Premium!$A$21:$A$29,0),MATCH(EOMONTH(MAIN!H50,-1)+1,Premium!$A$21:$D$21,0)) -> -2 | I31: Purchase Prem VS Barges | J31: =INDEX(Premium!$A$21:$D$29,MATCH(MAIN!$A29,Premium!$A$21:$A$29,0),MATCH(EOMONTH(MAIN!J50,-1)+1,Premium!$A$21:$D$21,0)) -> -2 | K31: =INDEX(Premium!$A$21:$D$29,MATCH(MAIN!$A29,Premium!$A$21:$A$29,0),MATCH(EOMONTH(MAIN!K50,-1)+1,Premium!$A$21:$D$21,0)) -> -2 | L31: =INDEX(Premium!$A$21:$D$29,MATCH(MAIN!$A29,Premium!$A$21:$A$29,0),MATCH(EOMONTH(MAIN!L50,-1)+1,Premium!$A$21:$D$21,0)) -> -2
B32: Freight | C32: =INDEX('ROTT TO SING'!$A$8:$H$25,MATCH(MAIN!B32,'ROTT TO SING'!$A$8:$A$25,0),5) -> 20.740741 | D32: =INDEX('ROTT TO SING'!$A$8:$H$25,MATCH(MAIN!B32,'ROTT TO SING'!$A$8:$A$25,0),7) -> 20.740741 | E32: Freight | F32: =INDEX('ROTT TO SING'!$J$8:$S$25,MATCH(MAIN!E32,'ROTT TO SING'!$J$8:$J$25,0),5) -> 34 | G32: =INDEX('ROTT TO SING'!$J$8:$S$25,MATCH(MAIN!E32,'ROTT TO SING'!$J$8:$J$25,0),7) -> 34 | H32: =INDEX('ROTT TO SING'!$J$8:$S$25,MATCH(MAIN!E32,'ROTT TO SING'!$J$8:$J$25,0),9) -> 34 | I32: Freight | J32: =INDEX('ROTT TO SING'!$U$8:$AD$25,MATCH(MAIN!I32,'ROTT TO AG'!$L$6:$L$23,0),5) -> 46.938776 | K32: =INDEX('ROTT TO SING'!$U$8:$AD$25,MATCH(MAIN!I32,'ROTT TO AG'!$L$6:$L$23,0),7) -> 46.938776 | L32: =INDEX('ROTT TO SING'!$U$8:$AD$25,MATCH(MAIN!I32,'ROTT TO AG'!$L$6:$L$23,0),9) -> 46.938776
B33: Volume | C33: =INDEX('ROTT TO SING'!$A$8:$H$25,MATCH(MAIN!B33,'ROTT TO SING'!$A$8:$A$25,0),5) -> 0 | D33: =INDEX('ROTT TO SING'!$A$8:$H$25,MATCH(MAIN!B33,'ROTT TO SING'!$A$8:$A$25,0),7) -> 0 | E33: Volume | F33: =INDEX('ROTT TO SING'!$J$8:$S$25,MATCH(MAIN!E33,'ROTT TO SING'!$J$8:$J$25,0),5) -> 0 | G33: =INDEX('ROTT TO SING'!$J$8:$S$25,MATCH(MAIN!E33,'ROTT TO SING'!$J$8:$J$25,0),7) -> 0 | H33: =INDEX('ROTT TO SING'!$J$8:$S$25,MATCH(MAIN!E33,'ROTT TO SING'!$J$8:$J$25,0),9) -> 0 | I33: Volume | J33: =INDEX('ROTT TO SING'!$U$8:$AD$25,MATCH(MAIN!I33,'ROTT TO AG'!$L$6:$L$23,0),5) -> 0 | K33: =INDEX('ROTT TO SING'!$U$8:$AD$25,MATCH(MAIN!I33,'ROTT TO AG'!$L$6:$L$23,0),7) -> 0 | L33: =INDEX('ROTT TO SING'!$U$8:$AD$25,MATCH(MAIN!I33,'ROTT TO AG'!$L$6:$L$23,0),9) -> 0
B34: Demurrage | C34: =INDEX('ROTT TO SING'!$A$8:$H$25,MATCH(MAIN!B34,'ROTT TO SING'!$A$8:$A$25,0),5) -> 2.037037 | D34: =INDEX('ROTT TO SING'!$A$8:$H$25,MATCH(MAIN!B34,'ROTT TO SING'!$A$8:$A$25,0),7) -> 2.037037 | E34: Demurrage | F34: =INDEX('ROTT TO SING'!$J$8:$S$25,MATCH(MAIN!E34,'ROTT TO SING'!$J$8:$J$25,0),5) -> 2.6833333 | G34: =INDEX('ROTT TO SING'!$J$8:$S$25,MATCH(MAIN!E34,'ROTT TO SING'!$J$8:$J$25,0),7) -> 2.6833333 | H34: =INDEX('ROTT TO SING'!$J$8:$S$25,MATCH(MAIN!E34,'ROTT TO SING'!$J$8:$J$25,0),9) -> 2.6833333 | I34: Demurrage | J34: =INDEX('ROTT TO SING'!$U$8:$AD$25,MATCH(MAIN!I34,'ROTT TO AG'!$L$6:$L$23,0),5) -> 2.1683673 | K34: =INDEX('ROTT TO SING'!$U$8:$AD$25,MATCH(MAIN!I34,'ROTT TO AG'!$L$6:$L$23,0),7) -> 2.1683673 | L34: =INDEX('ROTT TO SING'!$U$8:$AD$25,MATCH(MAIN!I34,'ROTT TO AG'!$L$6:$L$23,0),9) -> 2.1683673
B35: Insurance | C35: =INDEX('ROTT TO SING'!$A$8:$H$25,MATCH(MAIN!B35,'ROTT TO SING'!$A$8:$A$25,0),5) -> 0.031481481 | D35: =INDEX('ROTT TO SING'!$A$8:$H$25,MATCH(MAIN!B35,'ROTT TO SING'!$A$8:$A$25,0),7) -> 0.031481481 | E35: Insurance | F35: =INDEX('ROTT TO SING'!$J$8:$S$25,MATCH(MAIN!E35,'ROTT TO SING'!$J$8:$J$25,0),5) -> 0.056666667 | G35: =INDEX('ROTT TO SING'!$J$8:$S$25,MATCH(MAIN!E35,'ROTT TO SING'!$J$8:$J$25,0),7) -> 0.056666667 | H35: =INDEX('ROTT TO SING'!$J$8:$S$25,MATCH(MAIN!E35,'ROTT TO SING'!$J$8:$J$25,0),9) -> 0.056666667 | I35: Insurance | J35: =INDEX('ROTT TO SING'!$U$8:$AD$25,MATCH(MAIN!I35,'ROTT TO AG'!$L$6:$L$23,0),5) -> 0.086734694 | K35: =INDEX('ROTT TO SING'!$U$8:$AD$25,MATCH(MAIN!I35,'ROTT TO AG'!$L$6:$L$23,0),7) -> 0.086734694 | L35: =INDEX('ROTT TO SING'!$U$8:$AD$25,MATCH(MAIN!I35,'ROTT TO AG'!$L$6:$L$23,0),9) -> 0.086734694
B36: Loading PC | C36: =INDEX('ROTT TO SING'!$A$8:$H$25,MATCH(MAIN!B36,'ROTT TO SING'!$A$8:$A$25,0),5) -> 0.092592593 | D36: =INDEX('ROTT TO SING'!$A$8:$H$25,MATCH(MAIN!B36,'ROTT TO SING'!$A$8:$A$25,0),7) -> 0.092592593 | E36: Loading PC | F36: =INDEX('ROTT TO SING'!$J$8:$S$25,MATCH(MAIN!E36,'ROTT TO SING'!$J$8:$J$25,0),5) -> 0.16666667 | G36: =INDEX('ROTT TO SING'!$J$8:$S$25,MATCH(MAIN!E36,'ROTT TO SING'!$J$8:$J$25,0),7) -> 0.16666667 | H36: =INDEX('ROTT TO SING'!$J$8:$S$25,MATCH(MAIN!E36,'ROTT TO SING'!$J$8:$J$25,0),9) -> 0.16666667 | I36: Loading PC | J36: =INDEX('ROTT TO SING'!$U$8:$AD$25,MATCH(MAIN!I36,'ROTT TO AG'!$L$6:$L$23,0),5) -> 0.25510204 | K36: =INDEX('ROTT TO SING'!$U$8:$AD$25,MATCH(MAIN!I36,'ROTT TO AG'!$L$6:$L$23,0),7) -> 0.25510204 | L36: =INDEX('ROTT TO SING'!$U$8:$AD$25,MATCH(MAIN!I36,'ROTT TO AG'!$L$6:$L$23,0),9) -> 0.25510204
B37: Discharge PC | C37: =INDEX('ROTT TO SING'!$A$8:$H$25,MATCH(MAIN!B37,'ROTT TO SING'!$A$8:$A$25,0),5) -> 0.092592593 | D37: =INDEX('ROTT TO SING'!$A$8:$H$25,MATCH(MAIN!B37,'ROTT TO SING'!$A$8:$A$25,0),7) -> 0.092592593 | E37: Discharge PC | F37: =INDEX('ROTT TO SING'!$J$8:$S$25,MATCH(MAIN!E37,'ROTT TO SING'!$J$8:$J$25,0),5) -> 0.16666667 | G37: =INDEX('ROTT TO SING'!$J$8:$S$25,MATCH(MAIN!E37,'ROTT TO SING'!$J$8:$J$25,0),7) -> 0.16666667 | H37: =INDEX('ROTT TO SING'!$J$8:$S$25,MATCH(MAIN!E37,'ROTT TO SING'!$J$8:$J$25,0),9) -> 0.16666667 | I37: Discharge PC | J37: =INDEX('ROTT TO SING'!$U$8:$AD$25,MATCH(MAIN!I37,'ROTT TO AG'!$L$6:$L$23,0),5) -> 0.25510204 | K37: =INDEX('ROTT TO SING'!$U$8:$AD$25,MATCH(MAIN!I37,'ROTT TO AG'!$L$6:$L$23,0),7) -> 0.25510204 | L37: =INDEX('ROTT TO SING'!$U$8:$AD$25,MATCH(MAIN!I37,'ROTT TO AG'!$L$6:$L$23,0),9) -> 0.25510204
B38: Finance | C38: =INDEX('ROTT TO SING'!$A$8:$H$25,MATCH(MAIN!B38,'ROTT TO SING'!$A$8:$A$25,0),5) -> 3.465 | D38: =INDEX('ROTT TO SING'!$A$8:$H$25,MATCH(MAIN!B38,'ROTT TO SING'!$A$8:$A$25,0),7) -> 3.465 | E38: Finance | F38: =INDEX('ROTT TO SING'!$J$8:$S$25,MATCH(MAIN!E38,'ROTT TO SING'!$J$8:$J$25,0),5) -> 3.465 | G38: =INDEX('ROTT TO SING'!$J$8:$S$25,MATCH(MAIN!E38,'ROTT TO SING'!$J$8:$J$25,0),7) -> 3.465 | H38: =INDEX('ROTT TO SING'!$J$8:$S$25,MATCH(MAIN!E38,'ROTT TO SING'!$J$8:$J$25,0),9) -> 3.4310959 | I38: Finance | J38: =INDEX('ROTT TO SING'!$U$8:$AD$25,MATCH(MAIN!I38,'ROTT TO AG'!$L$6:$L$23,0),5) -> 3.465 | K38: =INDEX('ROTT TO SING'!$U$8:$AD$25,MATCH(MAIN!I38,'ROTT TO AG'!$L$6:$L$23,0),7) -> 3.465 | L38: =INDEX('ROTT TO SING'!$U$8:$AD$25,MATCH(MAIN!I38,'ROTT TO AG'!$L$6:$L$23,0),9) -> 3.4310959
B39: Heat | C39: =INDEX('ROTT TO SING'!$A$8:$H$25,MATCH(MAIN!B39,'ROTT TO SING'!$A$8:$A$25,0),5) -> 0 | D39: =INDEX('ROTT TO SING'!$A$8:$H$25,MATCH(MAIN!B39,'ROTT TO SING'!$A$8:$A$25,0),7) -> 0 | E39: Heat | F39: =INDEX('ROTT TO SING'!$J$8:$S$25,MATCH(MAIN!E39,'ROTT TO SING'!$J$8:$J$25,0),5) -> 0 | G39: =INDEX('ROTT TO SING'!$J$8:$S$25,MATCH(MAIN!E39,'ROTT TO SING'!$J$8:$J$25,0),7) -> 0 | H39: =INDEX('ROTT TO SING'!$J$8:$S$25,MATCH(MAIN!E39,'ROTT TO SING'!$J$8:$J$25,0),9) -> 0 | I39: Heat | J39: =INDEX('ROTT TO SING'!$U$8:$AD$25,MATCH(MAIN!I39,'ROTT TO AG'!$L$6:$L$23,0),5) -> 0 | K39: =INDEX('ROTT TO SING'!$U$8:$AD$25,MATCH(MAIN!I39,'ROTT TO AG'!$L$6:$L$23,0),7) -> 0 | L39: =INDEX('ROTT TO SING'!$U$8:$AD$25,MATCH(MAIN!I39,'ROTT TO AG'!$L$6:$L$23,0),9) -> 0
B40: LC charges | C40: =INDEX('ROTT TO SING'!$A$8:$H$25,MATCH(MAIN!B40,'ROTT TO SING'!$A$8:$A$25,0),5) -> 0.2874375 | D40: =INDEX('ROTT TO SING'!$A$8:$H$25,MATCH(MAIN!B40,'ROTT TO SING'!$A$8:$A$25,0),7) -> 0.2874375 | E40: LC charges | F40: =INDEX('ROTT TO SING'!$J$8:$S$25,MATCH(MAIN!E40,'ROTT TO SING'!$J$8:$J$25,0),5) -> 0.2874375 | G40: =INDEX('ROTT TO SING'!$J$8:$S$25,MATCH(MAIN!E40,'ROTT TO SING'!$J$8:$J$25,0),7) -> 0.2874375 | H40: =INDEX('ROTT TO SING'!$J$8:$S$25,MATCH(MAIN!E40,'ROTT TO SING'!$J$8:$J$25,0),9) -> 0.284625 | I40: LC charges | J40: =INDEX('ROTT TO SING'!$U$8:$AD$25,MATCH(MAIN!I40,'ROTT TO AG'!$L$6:$L$23,0),5) -> 0.2874375 | K40: =INDEX('ROTT TO SING'!$U$8:$AD$25,MATCH(MAIN!I40,'ROTT TO AG'!$L$6:$L$23,0),7) -> 0.2874375 | L40: =INDEX('ROTT TO SING'!$U$8:$AD$25,MATCH(MAIN!I40,'ROTT TO AG'!$L$6:$L$23,0),9) -> 0.284625
B41: Outturn loss | C41: =INDEX('ROTT TO SING'!$A$8:$H$25,MATCH(MAIN!B41,'ROTT TO SING'!$A$8:$A$25,0),5) -> 1.17975 | D41: =INDEX('ROTT TO SING'!$A$8:$H$25,MATCH(MAIN!B41,'ROTT TO SING'!$A$8:$A$25,0),7) -> 1.16925 | E41: Outturn loss | F41: =INDEX('ROTT TO SING'!$J$8:$S$25,MATCH(MAIN!E41,'ROTT TO SING'!$J$8:$J$25,0),5) -> 1.18125 | G41: =INDEX('ROTT TO SING'!$J$8:$S$25,MATCH(MAIN!E41,'ROTT TO SING'!$J$8:$J$25,0),7) -> 1.17975 | H41: =INDEX('ROTT TO SING'!$J$8:$S$25,MATCH(MAIN!E41,'ROTT TO SING'!$J$8:$J$25,0),9) -> 1.17975 | I41: Outturn loss | J41: =INDEX('ROTT TO SING'!$U$8:$AD$25,MATCH(MAIN!I41,'ROTT TO AG'!$L$6:$L$23,0),5) -> 1.18125 | K41: =INDEX('ROTT TO SING'!$U$8:$AD$25,MATCH(MAIN!I41,'ROTT TO AG'!$L$6:$L$23,0),7) -> 1.17975 | L41: =INDEX('ROTT TO SING'!$U$8:$AD$25,MATCH(MAIN!I41,'ROTT TO AG'!$L$6:$L$23,0),9) -> 1.17975
B42: Inspection | C42: =INDEX('ROTT TO SING'!$A$8:$H$25,MATCH(MAIN!B42,'ROTT TO SING'!$A$8:$A$25,0),5) -> 0.046296296 | D42: =INDEX('ROTT TO SING'!$A$8:$H$25,MATCH(MAIN!B42,'ROTT TO SING'!$A$8:$A$25,0),7) -> 0.046296296 | E42: Inspection | F42: =INDEX('ROTT TO SING'!$J$8:$S$25,MATCH(MAIN!E42,'ROTT TO SING'!$J$8:$J$25,0),5) -> 0.083333333 | G42: =INDEX('ROTT TO SING'!$J$8:$S$25,MATCH(MAIN!E42,'ROTT TO SING'!$J$8:$J$25,0),7) -> 0.083333333 | H42: =INDEX('ROTT TO SING'!$J$8:$S$25,MATCH(MAIN!E42,'ROTT TO SING'!$J$8:$J$25,0),9) -> 0.083333333 | I42: Inspection | J42: =INDEX('ROTT TO SING'!$U$8:$AD$25,MATCH(MAIN!I42,'ROTT TO AG'!$L$6:$L$23,0),5) -> 0.12755102 | K42: =INDEX('ROTT TO SING'!$U$8:$AD$25,MATCH(MAIN!I42,'ROTT TO AG'!$L$6:$L$23,0),7) -> 0.12755102 | L42: =INDEX('ROTT TO SING'!$U$8:$AD$25,MATCH(MAIN!I42,'ROTT TO AG'!$L$6:$L$23,0),9) -> 0.12755102
B43: Overage Insurance | C43: =INDEX('ROTT TO SING'!$A$8:$H$25,MATCH(MAIN!B43,'ROTT TO SING'!$A$8:$A$25,0),5) -> 0.0046296296 | D43: =INDEX('ROTT TO SING'!$A$8:$H$25,MATCH(MAIN!B43,'ROTT TO SING'!$A$8:$A$25,0),7) -> 0.0046296296 | E43: Overage Insurance | F43: =INDEX('ROTT TO SING'!$J$8:$S$25,MATCH(MAIN!E43,'ROTT TO SING'!$J$8:$J$25,0),5) -> 0.0083333333 | G43: =INDEX('ROTT TO SING'!$J$8:$S$25,MATCH(MAIN!E43,'ROTT TO SING'!$J$8:$J$25,0),7) -> 0.0083333333 | H43: =INDEX('ROTT TO SING'!$J$8:$S$25,MATCH(MAIN!E43,'ROTT TO SING'!$J$8:$J$25,0),9) -> 0.0083333333 | I43: Overage Insurance | J43: =INDEX('ROTT TO SING'!$U$8:$AD$25,MATCH(MAIN!I43,'ROTT TO AG'!$L$6:$L$23,0),5) -> 0.012755102 | K43: =INDEX('ROTT TO SING'!$U$8:$AD$25,MATCH(MAIN!I43,'ROTT TO AG'!$L$6:$L$23,0),7) -> 0.012755102 | L43: =INDEX('ROTT TO SING'!$U$8:$AD$25,MATCH(MAIN!I43,'ROTT TO AG'!$L$6:$L$23,0),9) -> 0.012755102
... B49: ROLL - COST | C49: =INDEX('ROTT TO SING'!$A$8:$H$25,MATCH(MAIN!B49,'ROTT TO SING'!$A$8:$A$25,0),5) -> -17.956935 | D49: =INDEX('ROTT TO SING'!$A$8:$H$25,MATCH(MAIN!B49,'ROTT TO SING'!$A$8:$A$25,0),7) -> -17.681283 | E49: ROLL - COST | F49: =INDEX('ROTT TO SING'!$J$8:$S$25,MATCH(MAIN!E49,'ROTT TO SING'!$J$8:$J$25,0),5) -> -32.273688 | G49: =INDEX('ROTT TO SING'!$J$8:$S$25,MATCH(MAIN!E49,'ROTT TO SING'!$J$8:$J$25,0),7) -> -32.147188 | H49: =INDEX('ROTT TO SING'!$J$8:$S$25,MATCH(MAIN!E49,'ROTT TO SING'!$J$8:$J$25,0),9) -> -31.985471 | I49: ROLL - COST | J49: =INDEX('ROTT TO SING'!$U$8:$AD$25,MATCH(MAIN!I49,'ROTT TO AG'!$L$6:$L$23,0),5) -> -45.045932 | K49: =INDEX('ROTT TO SING'!$U$8:$AD$25,MATCH(MAIN!I49,'ROTT TO AG'!$L$6:$L$23,0),7) -> -44.919432 | L49: =INDEX('ROTT TO SING'!$U$8:$AD$25,MATCH(MAIN!I49,'ROTT TO AG'!$L$6:$L$23,0),9) -> -44.757716
B50: Loading Month | C50: =C28 -> 45910 | D50: =D28 -> 45924 | E50: Loading Month | F50: =F28 -> 45903 | G50: =G28 -> 45917 | H50: =H28 -> 45931 | I50: Loading Month | J50: =J28 -> 45903 | K50: =K28 -> 45944 | L50: =L28 -> 45958
B52: VS 0.5% | C52: =IF(DAY(C$6)<15,"1H-"&VLOOKUP(MONTH(C$6),Mapping!$A$1:$B$12,2,0),"2H-"&VLOOKUP(MONTH(C$6),Mapping!$A$1:$B$12,2,0)) -> 2H-OCT | D52: =IF(DAY(D$6)<15,"1H-"&VLOOKUP(MONTH(D$6),Mapping!$A$1:$B$12,2,0),"2H-"&VLOOKUP(MONTH(D$6),Mapping!$A$1:$B$12,2,0)) -> 1H-NOV | F52: =IF(DAY(F$6)<15,"1H-"&VLOOKUP(MONTH(F$6),Mapping!$A$1:$B$12,2,0),"2H-"&VLOOKUP(MONTH(F$6),Mapping!$A$1:$B$12,2,0)) -> 2H-SEP | G52: =IF(DAY(G$6)<15,"1H-"&VLOOKUP(MONTH(G$6),Mapping!$A$1:$B$12,2,0),"2H-"&VLOOKUP(MONTH(G$6),Mapping!$A$1:$B$12,2,0)) -> 1H-OCT | H52: =IF(DAY(H$6)<15,"1H-"&VLOOKUP(MONTH(H$6),Mapping!$A$1:$B$12,2,0),"2H-"&VLOOKUP(MONTH(H$6),Mapping!$A$1:$B$12,2,0)) -> 2H-OCT | J52: =IF(DAY(J$6)<15,"1H-"&VLOOKUP(MONTH(J$6),Mapping!$A$1:$B$12,2,0),"2H-"&VLOOKUP(MONTH(J$6),Mapping!$A$1:$B$12,2,0)) -> 2H-SEP | K52: =IF(DAY(K$6)<15,"1H-"&VLOOKUP(MONTH(K$6),Mapping!$A$1:$B$12,2,0),"2H-"&VLOOKUP(MONTH(K$6),Mapping!$A$1:$B$12,2,0)) -> 1H-OCT | L52: =IF(DAY(L$6)<15,"1H-"&VLOOKUP(MONTH(L$6),Mapping!$A$1:$B$12,2,0),"2H-"&VLOOKUP(MONTH(L$6),Mapping!$A$1:$B$12,2,0)) -> 2H-OCT
C53: =C6 -> 45955 | D53: =D6 -> 45969 | E53: =E6 -> 0 | F53: =F6 -> 45930 | G53: =G6 -> 45944 | H53: =H6 -> 45958 | I53: =I6 -> 0 | J53: =J6 -> 45930 | ... L53: =L6 -> 45958
A54: 1% RMG | C54: =C74+C55-C56 -> -23.153943 | D54: =D74+D55-D56 -> -22.423746 | F54: =F74+F55-F56 -> -38.288877 | G54: =G74+G55-G56 -> -37.412377 | H54: =H74+H55-H56 -> -36.493317 | J54: =J74+J55-J56 -> -51.061122 | K54: =K74+K55-K56 -> -50.184622 | L54: =L74+L55-L56 -> -49.265562
...

Sheet Premium
A1: SALES | J1: Departure
B2: 45901 | C2: 45931 | D2: 45962 | J2: Exact Date | K2: Month | O2: Row Labels
A3: Singapore DES VALUES VS 380 | J3: ='Loading Arrival'!B3 -> 45910 | K3: =EOMONTH(J3,-1)+1 -> 45901 | O3: 01.11.2024
A4: RMG | B4: -1.5 | C4: -1.5 | D4: -1.5 | J4: ='Loading Arrival'!C3 -> 45924 | K4: =EOMONTH(J4,-1)+1 -> 45901 | O4: 01.12.2024
A5: RMK | B5: =+B4-5 -> -6.5 | C5: =+C4-5 -> -6.5 | D5: =+D4-5 -> -6.5 | J5: ='Loading Arrival'!D3 -> 45938 | K5: =EOMONTH(J5,-1)+1 -> 45931 | O5: Grand Total
A6: M100 | B6: -28 | C6: -28 | D6: -28 | J6: ='Loading Arrival'!B11 -> 45903 | K6: =EOMONTH(J6,-1)+1 -> 45901
A7: Singapore DES VALUES VS 0.5 | J7: ='Loading Arrival'!C11 -> 45917 | K7: =EOMONTH(J7,-1)+1 -> 45901
A8: 1% RMG | B8: -59 | C8: -59 | D8: -59 | J8: ='Loading Arrival'!D11 -> 45931 | K8: =EOMONTH(J8,-1)+1 -> 45931
A9: 0.5 | B9: 2.6 | C9: 2.6 | D9: 2.6
A10: AG DES VALUES VS MOPS 380 | J10: Arrivals
A11: RMG AG | B11: =B4-27.67 -> -29.17 | C11: =C4-27.67 -> -29.17 | D11: =D4-27.67 -> -29.17 | J11: Exact Date | K11: Month | O11: Row Labels
A12: RMK AG | B12: =B11-5 -> -34.17 | C12: =C11-5 -> -34.17 | D12: =D11-5 -> -34.17 | J12: ='Loading Arrival'!B9 -> 45955 | K12: =EOMONTH(J12,-1)+1 -> 45931 | O12: 01.11.2024
A13: USGC DES VALUES VS 3.5 ROTT | J13: ='Loading Arrival'!C9 -> 45969 | K13: =EOMONTH(J13,-1)+1 -> 45962 | O13: 01.12.2024 | T13: 840
A14: RMG US | B14: =0.6*6.35 -> 3.81 | C14: =1.1*6.35 -> 6.985 | D14: =1.1*6.35 -> 6.985 | J14: ='Loading Arrival'!B17 -> 45930 | K14: =EOMONTH(J14,-1)+1 -> 45901 | O14: 01.01.2025 | R14: QTY | S14: Premim | T14: Visco | U14: DESC | V14: FINAL P
A15: 0.5 US | B15: =1.6*6.35 -> 10.16 | C15: =1.05*6.35 -> 6.6675 | D15: =0.55*6.35 -> 3.4925 | J15: ='Loading Arrival'!C17 -> 45944 | K15: =EOMONTH(J15,-1)+1 -> 45931 | O15: Grand Total | R15: 44745 | S15: -31 | T15: 1008 | U15: =(T15-T13)*-0.02 -> -3.36 | V15: =U15+S15 -> -34.36
A16: MED PREMIUMS | J16: ='Loading Arrival'!D17 -> 45958 | K16: =EOMONTH(J16,-1)+1 -> 45931 | R16: 27000 | S16: -21.85 | T16: 418 | U16: =(T16-T13)*-0.02 -> 8.44 | V16: =U16+S16 -> -13.41
A17: RMG MED | J17: ='Loading Arrival'!B26 -> 45922 | K17: =EOMONTH(J17,-1)+1 -> 45901
A18: 0.5 MED | J18: ='Loading Arrival'!C26 -> 45936 | K18: =EOMONTH(J18,-1)+1 -> 45931 | U18: Weighted AVG P | V18: =(R15*V15+R16*V16)/SUM(R15:R16) -> -26.475827
J19: ='Loading Arrival'!D26 -> 45950 | K19: =EOMONTH(J19,-1)+1 -> 45931
A20: Purchase | J20: ='Loading Arrival'!B35 -> 45923 | K20: =EOMONTH(J20,-1)+1 -> 45901
B21: 45901 | C21: 45931 | D21: 45962 | J21: ='Loading Arrival'!C35 -> 45937 | K21: =EOMONTH(J21,-1)+1 -> 45931
A22: Rotterdam FOB VALUE VS 3.5 Barges | J22: ='Loading Arrival'!D35 -> 45951 | K22: =EOMONTH(J22,-1)+1 -> 45931
A23: RMG | B23: 3 | C23: 3 | D23: 3 | J23: ='Loading Arrival'!B44 -> 45915 | K23: =EOMONTH(J23,-1)+1 -> 45901
A24: RMK | B24: =B23-5 -> -2 | C24: =C23-5 -> -2 | D24: =D23-5 -> -2 | J24: ='Loading Arrival'!C44 -> 45929 | K24: =EOMONTH(J24,-1)+1 -> 45901
A25: M100 | B25: -5 | C25: -5 | D25: -4 | J25: ='Loading Arrival'!D44 -> 45943 | K25: =EOMONTH(J25,-1)+1 -> 45931
A26: Rotterdam FOB VALUE VS 0.5 Rott | S26: * For the premium of the US just take the spreads at the settlement
A27: 1% RMG | B27: -35 | C27: =B27 -> -35 | D27: =C27 -> -35 | S27: *for the premium of the MED use the Tullet settlement report
A28: 0.5 | B28: 0.29 | C28: 0.29 | D28: 0.29 | P28: Singap window
A29: USGC DES VALUES VS 3.5 ROTT | P29: 3 | Q29: 0.5
A30: RMG US | B30: =0.6*6.35 -> 3.81 | C30: =1.1*6.35 -> 6.985 | D30: =0.65*6.35 -> 4.1275
A31: 0.5 US | B31: 2.54 | C31: 2.54 | D31: 2.54
A32: MED PREMIUMS
A33: RMG MED | B33: -8.5 | C33: -7.75 | D33: 7.75
A34: 0.5 MED | B34: 0 | C34: 0 | D34: 0

Sheet Freight
A1: Location | B1: Freight $/mt | D1: USD/MT | E1: Demurrage / Day | F1: Heat
A2: ROTT-AG AFRA | B2: 4200000 | D2: =B2/100000 -> 42 | E2: 42500 | F2: 0
A3: ROTT-AG SUEZ | B3: 4900000 | D3: =B3/150000 -> 32.666667 | E3: 57500 | F3: 0
A4: ROTT-SING AFRA | B4: 4600000 | D4: =B4/100000 -> 46 | E4: 42500 | F4: 0
A5: ROTT-SING SUEZ | B5: 5100000 | D5: =B5/150000 -> 34 | E5: 57500 | F5: 0
A6: ROTT-SING VLCC | B6: 5600000 | D6: =B6/270000 -> 20.740741 | E6: 55000 | F6: NA
A8: MED-AG AFRA | B8: 3700000 | D8: =B8/100000 -> 37 | E8: 42500 | F8: 0
A9: MED-AG SUEZ | B9: 4600000 | D9: =B9/150000 -> 30.666667 | E9: 57000 | F9: 0
A10: MED-SING AFRA | B10: 4300000 | D10: =B10/100000 -> 43 | E10: 42500 | F10: 0
A11: MED-SING SUEZ | B11: 4800000 | D11: =B11/150000 -> 32 | E11: 57500 | F11: 0
A13: ROTT-USGC AFRA | B13: 1747200 | D13: =B13/100000 -> 17.472 | E13: 42500
A14: ROTT USGC SUEZ | B14: 4258800 | D14: =B14/150000 -> 28.392 | E14: 57500

Sheet Loading Arrival
A1: Rott to Sing | F1: Rott to USGC
B2: FIX+BL | C2: FIX+BL +14 | D2: FIX+BL +28 | G2: FIX+BL | H2: FIX+BL +14 | I2: FIX+BL +28
A3: VLCC | B3: =TODAY()+14 -> 45910 | C3: =B3+14 -> 45924 | D3: =C3+14 -> 45938 | F3: AFRA/SUEZMAX | G3: =TODAY()+7 -> 45903 | H3: =G3+14 -> 45917 | I3: =H3+14 -> 45931
B4: =B5-B3 -> 21 | C4: =C5-C3 -> 7 | D4: =D5-D3 -> 24 | G4: =G5-G3 -> 28 | H4: =H5-H3 -> 14 | I4: =I5-I3 -> 31
B5: =EOMONTH(B3,0)+1 -> 45931 | C5: =EOMONTH(C3,0)+1 -> 45931 | D5: =EOMONTH(D3,0)+1 -> 45962 | G5: =EOMONTH(G3,0)+1 -> 45931 | H5: =EOMONTH(H3,0)+1 -> 45931 | I5: =EOMONTH(I3,0)+1 -> 45962
B6: =IF(45-B4>_xlfn.NUMBERVALUE(DAY(EOMONTH(B5,0))),_xlfn.NUMBERVALUE(DAY(EOMONTH(B5,0))),45-B4) -> 24 | C6: =IF(45-C4>_xlfn.NUMBERVALUE(DAY(EOMONTH(C5,0))),_xlfn.NUMBERVALUE(DAY(EOMONTH(C5,0))),45-C4) -> 31 | D6: =IF(45-D4>_xlfn.NUMBERVALUE(DAY(EOMONTH(D5,0))),_xlfn.NUMBERVALUE(DAY(EOMONTH(D5,0))),45-D4) -> 21 | G6: =IF(15-G4>_xlfn.NUMBERVALUE(DAY(EOMONTH(G5,0))),_xlfn.NUMBERVALUE(DAY(EOMONTH(G5,0))),15-G4) -> -13 | H6: =IF(15-H4>_xlfn.NUMBERVALUE(DAY(EOMONTH(H5,0))),_xlfn.NUMBERVALUE(DAY(EOMONTH(H5,0))),15-H4) -> 1 | I6: =IF(15-I4>_xlfn.NUMBERVALUE(DAY(EOMONTH(I5,0))),_xlfn.NUMBERVALUE(DAY(EOMONTH(I5,0))),15-I4) -> -16
B7: =B5+B6 -> 45955 | C7: =C5+C6 -> 45962 | D7: =D5+D6 -> 45983 | G7: =G5+G6 -> 45918 | H7: =H5+H6 -> 45932 | I7: =I5+I6 -> 45946
B8: =IF(45-B4>_xlfn.NUMBERVALUE(DAY(EOMONTH(B5,0))),45-B4-B6,0) -> 0 | C8: =IF(45-C4>_xlfn.NUMBERVALUE(DAY(EOMONTH(C5,0))),45-C4-C6,0) -> 7 | D8: =IF(45-D4>_xlfn.NUMBERVALUE(DAY(EOMONTH(D5,0))),45-D4-D6,0) -> 0 | G8: =IF(15-G4>_xlfn.NUMBERVALUE(DAY(EOMONTH(G5,0))),15-G4-G6,0) -> 0 | H8: =IF(15-H4>_xlfn.NUMBERVALUE(DAY(EOMONTH(H5,0))),15-H4-H6,0) -> 0 | I8: =IF(15-I4>_xlfn.NUMBERVALUE(DAY(EOMONTH(I5,0))),15-I4-I6,0) -> 0
B9: =B7+B8 -> 45955 | C9: =C7+C8 -> 45969 | D9: =D7+D8 -> 45983 | G9: =G7+G8 -> 45918 | H9: =H7+H8 -> 45932 | I9: =I7+I8 -> 45946
B10: FIX+BL | C10: FIX+BL +14 | D10: FIX+BL +28
A11: AFRA/SUEZMAX | B11: =TODAY()+7 -> 45903 | C11: =B11+14 -> 45917 | D11: =C11+14 -> 45931
B12: =B13-B11 -> 28 | C12: =C13-C11 -> 14 | D12: =D13-D11 -> 31
B13: =EOMONTH(B11,0)+1 -> 45931 | C13: =EOMONTH(C11,0)+1 -> 45931 | D13: =EOMONTH(D11,0)+1 -> 45962
B14: =IF(27-B12>_xlfn.NUMBERVALUE(DAY(EOMONTH(B13,0))),_xlfn.NUMBERVALUE(DAY(EOMONTH(B13,0))),27-B12) -> -1 | C14: =IF(27-C12>_xlfn.NUMBERVALUE(DAY(EOMONTH(C13,0))),_xlfn.NUMBERVALUE(DAY(EOMONTH(C13,0))),27-C12) -> 13 | D14: =IF(27-D12>_xlfn.NUMBERVALUE(DAY(EOMONTH(D13,0))),_xlfn.NUMBERVALUE(DAY(EOMONTH(D13,0))),27-D12) -> -4
B15: =B13+B14 -> 45930 | C15: =C13+C14 -> 45944 | D15: =D13+D14 -> 45958
B16: =IF(27-B12>_xlfn.NUMBERVALUE(DAY(EOMONTH(B13,0))),30-B12-B14,0) -> 0 | C16: =IF(27-C12>_xlfn.NUMBERVALUE(DAY(EOMONTH(C13,0))),27-C12-C14,0) -> 0 | D16: =IF(27-D12>_xlfn.NUMBERVALUE(DAY(EOMONTH(D13,0))),27-D12-D14,0) -> 0
B17: =B15+B16 -> 45930 | C17: =C15+C16 -> 45944 | D17: =D15+D16 -> 45958
A18: Med to Sing
B19: FIX+BL | C19: FIX+BL +14 | D19: FIX+BL +28
A20: AFRA/SUEZMAX | B20: =TODAY()+7 -> 45903 | C20: =B20+14 -> 45917 | D20: =C20+14 -> 45931
B21: =B22-B20 -> 28 | C21: =C22-C20 -> 14 | D21: =D22-D20 -> 31
B22: =EOMONTH(B20,0)+1 -> 45931 | C22: =EOMONTH(C20,0)+1 -> 45931 | D22: =EOMONTH(D20,0)+1 -> 45962
B23: =IF(19-B21>_xlfn.NUMBERVALUE(DAY(EOMONTH(B22,0))),_xlfn.NUMBERVALUE(DAY(EOMONTH(B22,0))),19-B21) -> -9 | C23: =IF(19-C21>_xlfn.NUMBERVALUE(DAY(EOMONTH(C22,0))),_xlfn.NUMBERVALUE(DAY(EOMONTH(C22,0))),19-C21) -> 5 | D23: =IF(19-D21>_xlfn.NUMBERVALUE(DAY(EOMONTH(D22,0))),_xlfn.NUMBERVALUE(DAY(EOMONTH(D22,0))),19-D21) -> -12
B24: =B22+B23 -> 45922 | C24: =C22+C23 -> 45936 | D24: =D22+D23 -> 45950
B25: =IF(19-B21>_xlfn.NUMBERVALUE(DAY(EOMONTH(B22,0))),19-B21-B23,0) -> 0 | C25: =IF(19-C21>_xlfn.NUMBERVALUE(DAY(EOMONTH(C22,0))),19-C21-C23,0) -> 0 | D25: =IF(19-D21>_xlfn.NUMBERVALUE(DAY(EOMONTH(D22,0))),19-D21-D23,0) -> 0
B26: =B24+B25 -> 45922 | C26: =C24+C25 -> 45936 | D26: =D24+D25 -> 45950
A27: Rott to AG
B28: FIX+BL | C28: FIX+BL +14 | D28: FIX+BL +28
A29: AFRA/SUEZMAX | B29: =TODAY()+7 -> 45903 | C29: =B29+14 -> 45917 | D29: =C29+14 -> 45931
B30: =B31-B29 -> 28 | C30: =C31-C29 -> 14 | D30: =D31-D29 -> 31
B31: =EOMONTH(B29,0)+1 -> 45931 | C31: =EOMONTH(C29,0)+1 -> 45931 | D31: =EOMONTH(D29,0)+1 -> 45962
B32: =IF(20-B30>_xlfn.NUMBERVALUE(DAY(EOMONTH(B31,0))),_xlfn.NUMBERVALUE(DAY(EOMONTH(B31,0))),20-B30) -> -8 | C32: =IF(20-C30>_xlfn.NUMBERVALUE(DAY(EOMONTH(C31,0))),_xlfn.NUMBERVALUE(DAY(EOMONTH(C31,0))),20-C30) -> 6 | D32: =IF(20-D30>_xlfn.NUMBERVALUE(DAY(EOMONTH(D31,0))),_xlfn.NUMBERVALUE(DAY(EOMONTH(D31,0))),20-D30) -> -11
B33: =B31+B32 -> 45923 | C33: =C31+C32 -> 45937 | D33: =D31+D32 -> 45951
B34: =IF(20-B30>_xlfn.NUMBERVALUE(DAY(EOMONTH(B31,0))),20-B30-B32,0) -> 0 | C34: =IF(20-C30>_xlfn.NUMBERVALUE(DAY(EOMONTH(C31,0))),20-C30-C32,0) -> 0 | D34: =IF(20-D30>_xlfn.NUMBERVALUE(DAY(EOMONTH(D31,0))),20-D30-D32,0) -> 0
B35: =B33+B34 -> 45923 | C35: =C33+C34 -> 45937 | D35: =D33+D34 -> 45951
A36: Med to AG
B37: FIX+BL | C37: FIX+BL +14 | D37: FIX+BL +28
A38: AFRA/SUEZMAX | B38: =TODAY()+7 -> 45903 | C38: =B38+14 -> 45917 | D38: =C38+14 -> 45931
B39: =B40-B38 -> 12 | C39: =IF(C40-C38>12,12,C40-C38) -> 12 | D39: =D40-D38 -> 12
B40: =IF(EOMONTH(B38,0)+1-B38>12,B38+12,EOMONTH(B38,0)+1) -> 45915 | C40: =IF(EOMONTH(C38,0)+1-C38>12,C38+12,EOMONTH(C38,0)+1) -> 45929 | D40: =IF(EOMONTH(D38,0)+1-D38>12,D38+12,EOMONTH(D38,0)+1) -> 45943
...

Sheet ROTT TO USGC
E3: FIX+BL | G3: FIX+BL +14 | I3: FIX+BL +28 | P3: FIX+BL | R3: FIX+BL +14 | T3: FIX+BL +28
A4: ROTT USGC SUEZ | E4: ='Loading Arrival'!B11 -> 45903 | G4: ='Loading Arrival'!C11 -> 45917 | I4: ='Loading Arrival'!D11 -> 45931 | L4: ROTT-USGC AFRA | P4: =E4 -> 45903 | R4: =G4 -> 45917 | T4: =I4 -> 45931
E5: HS | F5: LS | G5: HS | H5: LS | I5: HS | J5: LS | P5: HS | Q5: LS | R5: HS | S5: LS | T5: HS | U5: LS
A6: Freight | B6: =VLOOKUP(A4,Freight!$A$2:$F$14,2,0) -> 4258800 | E6: =B6/B$7 -> 28.392 | F6: =B6/B$7 -> 28.392 | G6: =B6/B$7 -> 28.392 | H6: =B6/B$7 -> 28.392 | I6: =B6/B$7 -> 28.392 | J6: =B6/B$7 -> 28.392 | L6: Freight | M6: =VLOOKUP(L4,Freight!$A$2:$F$14,2,0) -> 1747200 | P6: =M6/M$7 -> 17.828571 | Q6: =M6/M$7 -> 17.828571 | R6: =M6/M$7 -> 17.828571 | S6: =M6/M$7 -> 17.828571 | T6: =M6/M$7 -> 17.828571 | U6: =M6/M$7 -> 17.828571
A7: Volume | B7: 150000 | C7: Rate | D7: Days | L7: Volume | M7: 98000 | N7: Rate | O7: Days
A8: Demurrage | B8: =C8*D8 -> 575000 | C8: =VLOOKUP(A$4,Freight!$A$2:$F$14,5,0) -> 57500 | D8: 10 | E8: =B$8/B$7 -> 3.8333333 | F8: =B$8/B$7 -> 3.8333333 | G8: =B8/B$7 -> 3.8333333 | H8: =B8/B$7 -> 3.8333333 | I8: =B8/B$7 -> 3.8333333 | J8: =B8/B$7 -> 3.8333333 | L8: Demurrage | M8: =N8*O8 -> 297500 | N8: =VLOOKUP(L$4,Freight!$A$2:$F$14,5,0) -> 42500 | O8: 7 | P8: =M$8/M$7 -> 3.0357143 | Q8: =M$8/M$7 -> 3.0357143 | R8: =M8/M$7 -> 3.0357143 | S8: =M8/M$7 -> 3.0357143 | T8: =M8/M$7 -> 3.0357143 | U8: =M8/M$7 -> 3.0357143
A9: Insurance | B9: 15000 | E9: =B9/B$7 -> 0.1 | F9: =B9/B$7 -> 0.1 | G9: =B9/B$7 -> 0.1 | H9: =B9/B$7 -> 0.1 | I9: =B9/B$7 -> 0.1 | J9: =B9/B$7 -> 0.1 | L9: Insurance | M9: 15000 | P9: =M9/M$7 -> 0.15306122 | Q9: =M9/M$7 -> 0.15306122 | R9: =M9/M$7 -> 0.15306122 | S9: =M9/M$7 -> 0.15306122 | T9: =M9/M$7 -> 0.15306122 | U9: =M9/M$7 -> 0.15306122
A10: Loading PC | B10: 25000 | E10: =B10/B$7 -> 0.16666667 | F10: =B10/B$7 -> 0.16666667 | G10: =B10/B$7 -> 0.16666667 | H10: =B10/B$7 -> 0.16666667 | I10: =B10/B$7 -> 0.16666667 | J10: =B10/B$7 -> 0.16666667 | L10: Loading PC | M10: 25000 | P10: =M10/M$7 -> 0.25510204 | Q10: =M10/M$7 -> 0.25510204 | R10: =M10/M$7 -> 0.25510204 | S10: =M10/M$7 -> 0.25510204 | T10: =M10/M$7 -> 0.25510204 | U10: =M10/M$7 -> 0.25510204
A11: Discharge PC | B11: 25000 | C11: Rate | D11: Days | E11: =B11/B$7 -> 0.16666667 | F11: =B11/B$7 -> 0.16666667 | G11: =B11/B$7 -> 0.16666667 | H11: =B11/B$7 -> 0.16666667 | I11: =B11/B$7 -> 0.16666667 | J11: =B11/B$7 -> 0.16666667 | L11: Discharge PC | M11: 25000 | N11: Rate | O11: Days | P11: =M11/M$7 -> 0.25510204 | Q11: =M11/M$7 -> 0.25510204 | R11: =M11/M$7 -> 0.25510204 | S11: =M11/M$7 -> 0.25510204 | T11: =M11/M$7 -> 0.25510204 | U11: =M11/M$7 -> 0.25510204
A12: Finance | B12: =(D12*((C12)/365)*VLOOKUP(EOMONTH(E4,-1)+1,Tullet!$A$4:$S$25,2,0))*B7 -> 519750 | C12: 0.055 | D12: 60 | E12: =(D12*((C12)/365)*VLOOKUP(EOMONTH(E4,-1)+1,Tullet!$A$4:$S$27,2,0)) -> 3.465 | F12: =(D12*((C12)/365)*VLOOKUP(EOMONTH(E4,-1)+1,Tullet!$N$4:$S$27,3,0)) -> 4.0907787 | G12: =(D$12*((C$12)/365)*VLOOKUP(EOMONTH(G4,-1)+1,Tullet!$A$4:$S$27,2,0)) -> 3.465 | H12: =(D$12*((C$12)/365)*VLOOKUP(EOMONTH(G4,-1)+1,Tullet!$N$4:$S$27,3,0)) -> 4.0907787 | I12: =(D$12*((C$12)/365)*VLOOKUP(EOMONTH(I4,-1)+1,Tullet!$A$4:$S$27,2,0)) -> 3.4310959 | J12: =(D$12*((C$12)/365)*VLOOKUP(EOMONTH(I4,-1)+1,Tullet!$N$4:$S$27,3,0)) -> 4.0500938 | L12: Finance | M12: =(O12*((N12)/365)*VLOOKUP(EOMONTH(P4,-1)+1,Tullet!$A$4:$S$25,2,0))*M7 -> 339570 | N12: 0.055 | O12: 60 | P12: =(O12*((N12)/365)*VLOOKUP(EOMONTH(P4,-1)+1,Tullet!$A$4:$S$27,2,0)) -> 3.465 | Q12: =(O12*((N12)/365)*VLOOKUP(EOMONTH(P4,-1)+1,Tullet!$N$4:$S$27,3,0)) -> 4.0907787 | R12: =(O$12*((N$12)/365)*VLOOKUP(EOMONTH(R4,-1)+1,Tullet!$A$4:$S$27,2,0)) -> 3.465 | S12: =(O$12*((N$12)/365)*VLOOKUP(EOMONTH(R4,-1)+1,Tullet!$N$4:$S$27,3,0)) -> 4.0907787 | T12: =(O$12*((N$12)/365)*VLOOKUP(EOMONTH(T4,-1)+1,Tullet!$A$4:$S$27,2,0)) -> 3.4310959 | U12: =(O$12*((N$12)/365)*VLOOKUP(EOMONTH(T4,-1)+1,Tullet!$N$4:$S$27,3,0)) -> 4.0500938
A13: Heat | L13: Heat
A14: LC charges | B14: =B7*VLOOKUP(EOMONTH(E4,-1)+1,Tullet!$A$4:$S$25,2,0)*0.1% -> 57487.5 | C14: Rate | D14: Quote | E14: =VLOOKUP(EOMONTH(E4,-1)+1,Tullet!$A$4:$S$27,2,0)*0.00075 -> 0.2874375 | F14: =VLOOKUP(EOMONTH(E4,-1)+1,Tullet!$N$3:$S$27,3,0)*0.00075 -> 0.33934869 | G14: =VLOOKUP(EOMONTH(G4,-1)+1,Tullet!$A$4:$S$27,2,0)*0.00075 -> 0.2874375 | H14: =VLOOKUP(EOMONTH(G4,-1)+1,Tullet!$N$3:$S$27,3,0)*0.00075 -> 0.33934869 | I14: =VLOOKUP(EOMONTH(I4,-1)+1,Tullet!$A$4:$S$27,2,0)*0.00075 -> 0.284625 | J14: =VLOOKUP(EOMONTH(I4,-1)+1,Tullet!$N$3:$S$27,3,0)*0.00075 -> 0.33597369 | L14: LC charges | M14: =M7*VLOOKUP(EOMONTH(P4,-1)+1,Tullet!$A$4:$S$25,2,0)*0.1% -> 37558.5 | N14: Rate | O14: Quote | P14: =VLOOKUP(EOMONTH(P4,-1)+1,Tullet!$A$4:$S$27,2,0)*0.00075 -> 0.2874375 | Q14: =VLOOKUP(EOMONTH(P4,-1)+1,Tullet!$N$3:$S$27,3,0)*0.00075 -> 0.33934869 | R14: =VLOOKUP(EOMONTH(R4,-1)+1,Tullet!$A$4:$S$27,2,0)*0.00075 -> 0.2874375 | S14: =VLOOKUP(EOMONTH(R4,-1)+1,Tullet!$N$3:$S$27,3,0)*0.00075 -> 0.33934869 | T14: =VLOOKUP(EOMONTH(T4,-1)+1,Tullet!$A$4:$S$27,2,0)*0.00075 -> 0.284625 | U14: =VLOOKUP(EOMONTH(T4,-1)+1,Tullet!$N$3:$S$27,3,0)*0.00075 -> 0.33597369
A15: Outturn loss | B15: =C15*$B$7*VLOOKUP(EOMONTH(E24,-1)+1,'Tullet US'!$A$24:$C$32,3,0)*6.35 -> 165020.62 | C15: 0.003 | D15: HS GC HS | E15: =$C$15*VLOOKUP(EOMONTH(E24,-1)+1,'Tullet US'!$A$24:$C$32,3,0)*6.35 -> 1.1001375 | F15: =$C$15*VLOOKUP(EOMONTH(F24,-1)+1,'Tullet US'!$A$24:$C$32,3,0)*6.35 -> 1.1001375 | G15: =$C$15*VLOOKUP(EOMONTH(G24,-1)+1,'Tullet US'!$A$24:$C$32,3,0)*6.35 -> 1.0791825 | H15: =$C$15*VLOOKUP(EOMONTH(H24,-1)+1,'Tullet US'!$A$24:$C$32,3,0)*6.35 -> 1.0791825 | I15: =$C$15*VLOOKUP(EOMONTH(I24,-1)+1,'Tullet US'!$A$24:$C$32,3,0)*6.35 -> 1.0791825 | J15: =$C$15*VLOOKUP(EOMONTH(J24,-1)+1,'Tullet US'!$A$24:$C$32,3,0)*6.35 -> 1.0791825 | L15: Outturn loss | M15: =N15*$M$7*VLOOKUP(EOMONTH(P24,-1)+1,'Tullet US'!$A$24:$C$32,3,0)*6.35 -> 107813.48 | N15: 0.003 | O15: HS GC HS | P15: =$N$15*VLOOKUP(EOMONTH(P24,-1)+1,'Tullet US'!$A$24:$C$32,3,0)*6.35 -> 1.1001375 | Q15: =$N$15*VLOOKUP(EOMONTH(Q24,-1)+1,'Tullet US'!$A$24:$C$32,3,0)*6.35 -> 1.1001375 | R15: =$N$15*VLOOKUP(EOMONTH(R24,-1)+1,'Tullet US'!$A$24:$C$32,3,0)*6.35 -> 1.0791825 | S15: =$N$15*VLOOKUP(EOMONTH(S24,-1)+1,'Tullet US'!$A$24:$C$32,3,0)*6.35 -> 1.0791825 | T15: =$N$15*VLOOKUP(EOMONTH(T24,-1)+1,'Tullet US'!$A$24:$C$32,3,0)*6.35 -> 1.0791825 | U15: =$N$15*VLOOKUP(EOMONTH(U24,-1)+1,'Tullet US'!$A$24:$C$32,3,0)*6.35 -> 1.0791825
A16: Inspection | B16: 12500 | E16: =B16/B$7 -> 0.083333333 | F16: =B16/B$7 -> 0.083333333 | G16: =B16/B$7 -> 0.083333333 | H16: =B16/B$7 -> 0.083333333 | I16: =B16/B$7 -> 0.083333333 | J16: =B16/B$7 -> 0.083333333 | L16: Inspection | M16: 12500 | P16: =M16/M$7 -> 0.12755102 | Q16: =M16/M$7 -> 0.12755102 | R16: =M16/M$7 -> 0.12755102 | S16: =M16/M$7 -> 0.12755102 | T16: =M16/M$7 -> 0.12755102 | U16: =M16/M$7 -> 0.12755102
A17: Overage Insurance | B17: 1250 | E17: =B17/B$7 -> 0.0083333333 | F17: =B17/B$7 -> 0.0083333333 | G17: =B17/B$7 -> 0.0083333333 | H17: =B17/B$7 -> 0.0083333333 | I17: =B17/B$7 -> 0.0083333333 | J17: =B17/B$7 -> 0.0083333333 | L17: Overage Insurance | M17: 1250 | P17: =M17/M$7 -> 0.012755102 | Q17: =M17/M$7 -> 0.012755102 | R17: =M17/M$7 -> 0.012755102 | S17: =M17/M$7 -> 0.012755102 | T17: =M17/M$7 -> 0.012755102 | U17: =M17/M$7 -> 0.012755102
A18: CLL | B18: 1250 | E18: =B18/B$7 -> 0.0083333333 | F18: =B18/B$7 -> 0.0083333333 | G18: =B18/B$7 -> 0.0083333333 | H18: =B18/B$7 -> 0.0083333333 | I18: =B18/B$7 -> 0.0083333333 | J18: =B18/B$7 -> 0.0083333333 | L18: CLL | M18: 1250 | P18: =M18/M$7 -> 0.012755102 | Q18: =M18/M$7 -> 0.012755102 | R18: =M18/M$7 -> 0.012755102 | S18: =M18/M$7 -> 0.012755102 | T18: =M18/M$7 -> 0.012755102 | U18: =M18/M$7 -> 0.012755102
A19: Bank Charges | B19: 15000 | E19: =B19/B$7 -> 0.1 | F19: =B19/B$7 -> 0.1 | G19: =B19/B$7 -> 0.1 | H19: =B19/B$7 -> 0.1 | I19: =B19/B$7 -> 0.1 | J19: =B19/B$7 -> 0.1 | L19: Bank Charges | M19: 15000 | P19: =M19/M$7 -> 0.15306122 | Q19: =M19/M$7 -> 0.15306122 | R19: =M19/M$7 -> 0.15306122 | S19: =M19/M$7 -> 0.15306122 | T19: =M19/M$7 -> 0.15306122 | U19: =M19/M$7 -> 0.15306122
A20: Brokerages | B20: 10000 | E20: =B20/B$7 -> 0.066666667 | F20: =B20/B$7 -> 0.066666667 | G20: =B20/B$7 -> 0.066666667 | H20: =B20/B$7 -> 0.066666667 | I20: =B20/B$7 -> 0.066666667 | J20: =B20/B$7 -> 0.066666667 | L20: Brokerages | M20: 10000 | P20: =M20/M$7 -> 0.10204082 | Q20: =M20/M$7 -> 0.10204082 | R20: =M20/M$7 -> 0.10204082 | S20: =M20/M$7 -> 0.10204082 | T20: =M20/M$7 -> 0.10204082 | U20: =M20/M$7 -> 0.10204082
A21: TOTAL COST | B21: =SUM(B6:B20) -> 5831058.1 | E21: =SUM(E6:E20) -> 37.777908 | F21: =SUM(F6:F20) -> 38.455598 | G21: =SUM(G6:G20) -> 37.756953 | H21: =SUM(H6:H20) -> 38.434643 | I21: =SUM(I6:I20) -> 37.720237 | J21: =SUM(J6:J20) -> 38.390583 | L21: TOTAL COST | M21: =SUM(M6:M20) -> 2732642 | P21: =SUM(P6:P20) -> 26.788289 | Q21: =SUM(Q6:Q20) -> 27.465979 | R21: =SUM(R6:R20) -> 26.767334 | S21: =SUM(S6:S20) -> 27.445024 | T21: =SUM(T6:T20) -> 26.730618 | U21: =SUM(U6:U20) -> 27.400964
A22: ROLL | E22: ='ROLLS HS'!L54 -> -16.5375 | F22: ='ROLLS LS'!K54 -> 15.875 | G22: ='ROLLS HS'!L57 -> -17.076667 | H22: ='ROLLS LS'!K57 -> 15.5575 | I22: ='ROLLS HS'!L60 -> -19.7725 | J22: ='ROLLS LS'!K60 -> 13.97 | L22: ROLL | P22: =E22 -> -16.5375 | Q22: =F22 -> 15.875 | R22: =G22 -> -17.076667 | S22: =H22 -> 15.5575 | T22: =I22 -> -19.7725 | U22: =J22 -> 13.97
A23: ROLL - COST | E23: =E22-E21 -> -54.315408 | F23: =F22-F21 -> -22.580598 | G23: =G22-G21 -> -54.83362 | H23: =H22-H21 -> -22.877143 | I23: =I22-I21 -> -57.492737 | J23: =J22-J21 -> -24.420583 | L23: ROLL - COST | P23: =P22-P21 -> -43.325789 | Q23: =Q22-Q21 -> -11.590979 | R23: =R22-R21 -> -43.844001 | S23: =S22-S21 -> -11.887524 | T23: =T22-T21 -> -46.503118 | U23: =U22-U21 -> -13.430964
A24: Arrival Date | E24: ='Loading Arrival'!G9 -> 45918 | F24: ='Loading Arrival'!G9 -> 45918 | G24: ='Loading Arrival'!H9 -> 45932 | H24: ='Loading Arrival'!H9 -> 45932 | I24: ='Loading Arrival'!I9 -> 45946 | J24: ='Loading Arrival'!I9 -> 45946 | L24: Arrival Date | P24: =E24 -> 45918 | Q24: =F24 -> 45918 | R24: =G24 -> 45932 | S24: =H24 -> 45932 | T24: =I24 -> 45946 | U24: =J24 -> 45946
A25: Arrival | E25: ='Loading Arrival'!G9 -> 45918 | G25: ='Loading Arrival'!H9 -> 45932 | I25: ='Loading Arrival'!I9 -> 45946 | L25: Arrival | P25: =E25 -> 45918 | R25: =G25 -> 45932 | T25: =I25 -> 45946

Sheet ROTT TO SING
E3: FIX+BL | G3: FIX+BL +14 | N3: FIX+BL | P3: FIX+BL +14 | R3: FIX+BL +28 | Y3: FIX+BL | AA3: FIX+BL +14 | AC3: FIX+BL +28
A4: ROTT-SING VLCC | J4: ROTT-SING SUEZ | U4: ROTT-SING AFRA
A5: Month of departure | E5: ='Loading Arrival'!B3 -> 45910 | F5: =E5 -> 45910 | G5: ='Loading Arrival'!C3 -> 45924 | H5: =G5 -> 45924 | J5: Month of departure | N5: ='Loading Arrival'!$B$11 -> 45903 | O5: ='Loading Arrival'!$B$11 -> 45903 | P5: ='Loading Arrival'!$C$11 -> 45917 | Q5: ='Loading Arrival'!$C$11 -> 45917 | R5: ='Loading Arrival'!$D$11 -> 45931 | S5: ='Loading Arrival'!$D$11 -> 45931 | U5: Month of departure | Y5: ='Loading Arrival'!$B$11 -> 45903 | Z5: ='Loading Arrival'!$B$11 -> 45903 | AA5: ='Loading Arrival'!$C$11 -> 45917 | AB5: ='Loading Arrival'!$C$11 -> 45917 | AC5: ='Loading Arrival'!$D$11 -> 45931 | AD5: ='Loading Arrival'!$D$11 -> 45931
A6: Date of departure | E6: ='Loading Arrival'!B3 -> 45910 | F6: =E6 -> 45910 | G6: ='Loading Arrival'!C3 -> 45924 | H6: ='Loading Arrival'!C3 -> 45924 | J6: Date of departure | N6: =N5 -> 45903 | O6: =O5 -> 45903 | P6: =P5 -> 45917 | Q6: =Q5 -> 45917 | R6: =R5 -> 45931 | S6: =S5 -> 45931 | U6: Date of departure | Y6: =Y5 -> 45903 | Z6: =Z5 -> 45903 | AA6: =AA5 -> 45917 | AB6: =AB5 -> 45917 | AC6: =AC5 -> 45931 | AD6: =AD5 -> 45931
E7: HS | F7: LS | G7: HS | H7: LS | N7: HS | O7: LS | P7: HS | Q7: LS | R7: HS | S7: LS | Y7: HS | Z7: LS | AA7: HS | AB7: LS | AC7: HS | AD7: LS
A8: Freight | B8: =VLOOKUP(A4,Freight!$A$2:$F$11,2,0) -> 5600000 | E8: =$B8/$B$9 -> 20.740741 | F8: =$B8/$B$9 -> 20.740741 | G8: =B8/B$9 -> 20.740741 | H8: =B8/B$9 -> 20.740741 | J8: Freight | K8: =VLOOKUP(J4,Freight!$A$2:$F$11,2,0) -> 5100000 | N8: =K8/K$9 -> 34 | O8: =K8/K$9 -> 34 | P8: =K8/K$9 -> 34 | Q8: =K8/K$9 -> 34 | R8: =K8/K$9 -> 34 | S8: =K8/K$9 -> 34 | U8: Freight | V8: =VLOOKUP(U4,Freight!$A$2:$F$11,2,0) -> 4600000 | Y8: =V8/V$9 -> 46.938776 | Z8: =V8/V$9 -> 46.938776 | AA8: =V8/V$9 -> 46.938776 | AB8: =V8/V$9 -> 46.938776 | AC8: =V8/V$9 -> 46.938776 | AD8: =V8/V$9 -> 46.938776
A9: Volume | B9: 270000 | C9: Rate | D9: Days | J9: Volume | K9: 150000 | L9: Rate | M9: Days | U9: Volume | V9: 98000 | W9: Rate | X9: Days
A10: Demurrage | B10: =C10*D10 -> 550000 | C10: =VLOOKUP($A$4,Freight!$A$2:$F$11,5,0) -> 55000 | D10: 10 | E10: =B$10/B$9 -> 2.037037 | F10: =B$10/B$9 -> 2.037037 | G10: =B10/B$9 -> 2.037037 | H10: =B10/B$9 -> 2.037037 | J10: Demurrage | K10: =L10*M10 -> 402500 | L10: =VLOOKUP(J$4,Freight!$A$2:$F$11,5,0) -> 57500 | M10: 7 | N10: =K$10/K$9 -> 2.6833333 | O10: =K$10/K$9 -> 2.6833333 | P10: =K10/K$9 -> 2.6833333 | Q10: =K10/K$9 -> 2.6833333 | R10: =K10/K$9 -> 2.6833333 | S10: =K10/K$9 -> 2.6833333 | U10: Demurrage | V10: =W10*X10 -> 212500 | W10: =VLOOKUP(U$4,Freight!$A$2:$F$11,5,0) -> 42500 | X10: 5 | Y10: =V$10/V$9 -> 2.1683673 | Z10: =V$10/V$9 -> 2.1683673 | AA10: =V10/V$9 -> 2.1683673 | AB10: =V10/V$9 -> 2.1683673 | AC10: =V10/V$9 -> 2.1683673 | AD10: =V10/V$9 -> 2.1683673
A11: Insurance | B11: 8500 | E11: =B11/B$9 -> 0.031481481 | F11: =B11/B$9 -> 0.031481481 | G11: =B11/B$9 -> 0.031481481 | H11: =B11/B$9 -> 0.031481481 | J11: Insurance | K11: 8500 | N11: =K11/K$9 -> 0.056666667 | O11: =K11/K$9 -> 0.056666667 | P11: =K11/K$9 -> 0.056666667 | Q11: =K11/K$9 -> 0.056666667 | R11: =K11/K$9 -> 0.056666667 | S11: =K11/K$9 -> 0.056666667 | U11: Insurance | V11: 8500 | Y11: =V11/V$9 -> 0.086734694 | Z11: =V11/V$9 -> 0.086734694 | AA11: =V11/V$9 -> 0.086734694 | AB11: =V11/V$9 -> 0.086734694 | AC11: =V11/V$9 -> 0.086734694 | AD11: =V11/V$9 -> 0.086734694
A12: Loading PC | B12: 25000 | E12: =B12/B$9 -> 0.092592593 | F12: =B12/B$9 -> 0.092592593 | G12: =B12/B$9 -> 0.092592593 | H12: =B12/B$9 -> 0.092592593 | J12: Loading PC | K12: 25000 | N12: =K12/K$9 -> 0.16666667 | O12: =K12/K$9 -> 0.16666667 | P12: =K12/K$9 -> 0.16666667 | Q12: =K12/K$9 -> 0.16666667 | R12: =K12/K$9 -> 0.16666667 | S12: =K12/K$9 -> 0.16666667 | U12: Loading PC | V12: 25000 | Y12: =V12/V$9 -> 0.25510204 | Z12: =V12/V$9 -> 0.25510204 | AA12: =V12/V$9 -> 0.25510204 | AB12: =V12/V$9 -> 0.25510204 | AC12: =V12/V$9 -> 0.25510204 | AD12: =V12/V$9 -> 0.25510204
A13: Discharge PC | B13: 25000 | C13: Rate | D13: Days | E13: =B13/B$9 -> 0.092592593 | F13: =B13/B$9 -> 0.092592593 | G13: =B13/B$9 -> 0.092592593 | H13: =B13/B$9 -> 0.092592593 | J13: Discharge PC | K13: 25000 | L13: Rate | M13: Days | N13: =K13/K$9 -> 0.16666667 | O13: =K13/K$9 -> 0.16666667 | P13: =K13/K$9 -> 0.16666667 | Q13: =K13/K$9 -> 0.16666667 | R13: =K13/K$9 -> 0.16666667 | S13: =K13/K$9 -> 0.16666667 | U13: Discharge PC | V13: 25000 | W13: Rate | X13: Days | Y13: =V13/V$9 -> 0.25510204 | Z13: =V13/V$9 -> 0.25510204 | AA13: =V13/V$9 -> 0.25510204 | AB13: =V13/V$9 -> 0.25510204 | AC13: =V13/V$9 -> 0.25510204 | AD13: =V13/V$9 -> 0.25510204
A14: Finance | B14: =(D14*((C14)/365)*VLOOKUP(EOMONTH(E5,-1)+1,Tullet!$A$4:$S$25,2,0))*B9 -> 935550 | C14: 0.055 | D14: 60 | E14: =(D14*((C14)/365)*VLOOKUP(EOMONTH(E5,-1)+1,Tullet!$A$4:$S$27,2,0)) -> 3.465 | F14: =(D14*((C14)/365)*VLOOKUP(EOMONTH(E5,-1)+1,Tullet!$N$4:$S$27,3,0)) -> 4.0907787 | G14: =($D$14*(($C$14)/365)*VLOOKUP(EOMONTH(G5,-1)+1,Tullet!$A$4:$S$27,2,0)) -> 3.465 | H14: =($D$14*(($C$14)/365)*VLOOKUP(EOMONTH(G5,-1)+1,Tullet!$N$4:$S$27,3,0)) -> 4.0907787 | J14: Finance | K14: =(M14*((L14)/365)*VLOOKUP(EOMONTH(N5,-1)+1,Tullet!$A$4:$S$27,2,0))*K9 -> 519750 | L14: 0.055 | M14: 60 | N14: =(M14*((L14)/365)*VLOOKUP(EOMONTH(N5,-1)+1,Tullet!$A$4:$S$27,2,0)) -> 3.465 | O14: =(M14*((L14)/365)*VLOOKUP(EOMONTH(N5,-1)+1,Tullet!$N$4:$S$27,3,0)) -> 4.0907787 | P14: =(M$14*((L$14)/365)*VLOOKUP(EOMONTH(P5,-1)+1,Tullet!$A$4:$S$27,2,0)) -> 3.465 | Q14: =(M$14*((L$14)/365)*VLOOKUP(EOMONTH(P5,-1)+1,Tullet!$N$4:$S$27,3,0)) -> 4.0907787 | R14: =(M$14*((L$14)/365)*VLOOKUP(EOMONTH(R5,-1)+1,Tullet!$A$4:$S$27,2,0)) -> 3.4310959 | S14: =(M$14*((L$14)/365)*VLOOKUP(EOMONTH(R5,-1)+1,Tullet!$N$4:$S$27,3,0)) -> 4.0500938 | U14: Finance | V14: =(X14*((W14)/365)*VLOOKUP(EOMONTH(Y5,-1)+1,Tullet!$A$4:$S$27,2,0))*V9 -> 339570 | W14: 0.055 | X14: 60 | Y14: =(X14*((W14)/365)*VLOOKUP(EOMONTH(Y5,-1)+1,Tullet!$A$4:$S$27,2,0)) -> 3.465 | Z14: =(X14*((W14)/365)*VLOOKUP(EOMONTH(Y5,-1)+1,Tullet!$N$4:$S$27,3,0)) -> 4.0907787 | AA14: =(X$14*((W$14)/365)*VLOOKUP(EOMONTH(AA5,-1)+1,Tullet!$A$4:$S$27,2,0)) -> 3.465 | AB14: =(X$14*((W$14)/365)*VLOOKUP(EOMONTH(AA5,-1)+1,Tullet!$N$4:$S$27,3,0)) -> 4.0907787 | AC14: =(X$14*((W$14)/365)*VLOOKUP(EOMONTH(AC5,-1)+1,Tullet!$A$4:$S$27,2,0)) -> 3.4310959 | AD14: =(X$14*((W$14)/365)*VLOOKUP(EOMONTH(AC5,-1)+1,Tullet!$N$4:$S$27,3,0)) -> 4.0500938
A15: Heat | J15: Heat | U15: Heat
A16: LC charges | B16: =B9*VLOOKUP(EOMONTH(E5,-1)+1,Tullet!$A$4:$S$25,2,0)*0.1% -> 103477.5 | C16: Rate | D16: Quote | E16: =VLOOKUP(EOMONTH(E5,-1)+1,Tullet!$A$4:$S$27,2,0)*0.00075 -> 0.2874375 | F16: =VLOOKUP(EOMONTH(E5,-1)+1,Tullet!$N$3:$S$27,3,0)*0.00075 -> 0.33934869 | G16: =VLOOKUP(EOMONTH(G5,-1)+1,Tullet!$A$4:$S$27,2,0)*0.00075 -> 0.2874375 | H16: =VLOOKUP(EOMONTH(G5,-1)+1,Tullet!$N$3:$S$27,3,0)*0.00075 -> 0.33934869 | J16: LC charges | K16: =K9*VLOOKUP(EOMONTH(N5,-1)+1,Tullet!$A$4:$S$25,2,0)*0.1% -> 57487.5 | L16: Rate | M16: Quote | N16: =VLOOKUP(EOMONTH(N5,-1)+1,Tullet!$A$4:$S$27,2,0)*0.00075 -> 0.2874375 | O16: =VLOOKUP(EOMONTH(N5,-1)+1,Tullet!$N$3:$S$27,3,0)*0.00075 -> 0.33934869 | P16: =VLOOKUP(EOMONTH(P5,-1)+1,Tullet!$A$4:$S$27,2,0)*0.00075 -> 0.2874375 | Q16: =VLOOKUP(EOMONTH(P5,-1)+1,Tullet!$N$3:$S$27,3,0)*0.00075 -> 0.33934869 | R16: =VLOOKUP(EOMONTH(R5,-1)+1,Tullet!$A$4:$S$27,2,0)*0.00075 -> 0.284625 | S16: =VLOOKUP(EOMONTH(R5,-1)+1,Tullet!$N$3:$S$27,3,0)*0.00075 -> 0.33597369 | U16: LC charges | V16: =V9*VLOOKUP(EOMONTH(Y5,-1)+1,Tullet!$A$4:$S$25,2,0)*0.1% -> 37558.5 | W16: Rate | X16: Quote | Y16: =VLOOKUP(EOMONTH(Y5,-1)+1,Tullet!$A$4:$S$27,2,0)*0.00075 -> 0.2874375 | Z16: =VLOOKUP(EOMONTH(Y5,-1)+1,Tullet!$N$3:$S$27,3,0)*0.00075 -> 0.33934869 | AA16: =VLOOKUP(EOMONTH(AA5,-1)+1,Tullet!$A$4:$S$27,2,0)*0.00075 -> 0.2874375 | AB16: =VLOOKUP(EOMONTH(AA5,-1)+1,Tullet!$N$3:$S$27,3,0)*0.00075 -> 0.33934869 | AC16: =VLOOKUP(EOMONTH(AC5,-1)+1,Tullet!$A$4:$S$27,2,0)*0.00075 -> 0.284625 | AD16: =VLOOKUP(EOMONTH(AC5,-1)+1,Tullet!$N$3:$S$27,3,0)*0.00075 -> 0.33597369
